Workbook

Sheet 별첨1
A1: 별첨1. DT사업1팀 스케줄근무자 시간외근로수당 내역 (2026년 4월)
A2: No. | B2: 사번 | C2: 성명 | D2: 직급 | E2: 단위 조직 | F2: 구분 | G2: 근무 날짜 | H2: 근무 시간 | I2: 근로수당 현황 | R2: 통상시급 | S2: 지급 비용
I3: 기본 근로수당 | L3: 연장 근로수당 | O3: 야간 근로수당
I4: 시간 | J4: 요율 | K4: 수당 | L4: 시간 | M4: 요율 | N4: 수당 | O4: 시간 | P4: 요율 | Q4: 수당
A5: 1 | B5: 2024023 | C5: 박건우 | D5: - | E5: SKB동작국사 | F5: 연장근무 | G5: 2026.04.02 | H5: 1 | L5: 1 | M5: 1.5 | N5: 16760 | R5: 11173.59 | S5: 16760
A6: 2 | B6: 2024023 | C6: 박건우 | D6: - | E6: SKB동작국사 | F6: 연장근무 | G6: 2026.04.02 | H6: 1 | L6: 1 | M6: 1.5 | N6: 16760 | R6: 11173.59 | S6: 16760
A7: 3 | B7: 2014102 | C7: 박성호 | D7: - | E7: SKB동작국사 | F7: 연장근무 | G7: 2026.04.03 | H7: 1 | L7: 1 | M7: 1.5 | N7: 19348 | R7: 12898.79 | S7: 19348
A8: 4 | B8: 2014102 | C8: 박성호 | D8: - | E8: SKB동작국사 | F8: 연장근무 | G8: 2026.04.03 | H8: 1 | L8: 1 | M8: 1.5 | N8: 19348 | R8: 12898.79 | S8: 19348
A9: 5 | B9: 2020091 | C9: 고현재 | D9: - | E9: SKB동작국사 | F9: 연장근무 | G9: 2026.04.10 | H9: 1 | L9: 1 | M9: 1.5 | N9: 17186 | R9: 11457.12 | S9: 17186
A10: 6 | B10: 2020091 | C10: 고현재 | D10: - | E10: SKB동작국사 | F10: 연장근무 | G10: 2026.04.10 | H10: 1 | L10: 1 | M10: 1.5 | N10: 17186 | R10: 11457.12 | S10: 17186
A11: 7 | B11: 2026011 | C11: 주향모 | D11: - | E11: SKB동작국사 | F11: 연장근무 | G11: 2026.04.24 | H11: 1 | L11: 1 | M11: 1.5 | N11: 18024 | R11: 12015.67 | S11: 18024
A12: 8 | B12: 2026011 | C12: 주향모 | D12: - | E12: SKB동작국사 | F12: 연장근무 | G12: 2026.04.24 | H12: 1 | L12: 1 | M12: 1.5 | N12: 18024 | R12: 12015.67 | S12: 18024
A13: 9 | B13: 2020091 | C13: 고현재 | D13: - | E13: SKB동작국사 | F13: 연장근무 | G13: 2026.04.30 | H13: 1 | L13: 1 | M13: 1.5 | N13: 17186 | R13: 11457.12 | S13: 17186
A14: 10 | B14: 2020091 | C14: 고현재 | D14: - | E14: SKB동작국사 | F14: 연장근무 | G14: 2026.04.30 | H14: 1 | L14: 1 | M14: 1.5 | N14: 17186 | R14: 11457.12 | S14: 17186
A15: - | B15: - | C15: 소 계 | D15: - | E15: - | F15: - | G15: - | H15: 10 | I15: 10 | J15: - | K15: 177008 | L15: 10 | M15: - | N15: 177008 | O15: - | P15: - | Q15: - | R15: - | S15: 177008
A16: - | B16: - | C16: 합 계 | D16: - | E16: - | F16: 합계 | G16: - | H16: 10 | I16: 10 | J16: - | K16: 177008 | L16: 10 | M16: - | N16: 177008 | O16: - | P16: - | Q16: - | R16: - | S16: 177008
A18: ※ 5월 퇴사자 조기 지급 내역
A19: No. | B19: 사번 | C19: 성명 | D19: 직급 | E19: 단위 조직 | F19: 구분 | G19: 근무 날짜 | H19: 근무 시간 | I19: 근로수당 현황 | R19: 통상시급 | S19: 지급 비용
I20: 기본 근로수당 | L20: 연장 근로수당 | O20: 야간 근로수당
I21: 시간 | J21: 요율 | K21: 수당 | L21: 시간 | M21: 요율 | N21: 수당 | O21: 시간 | P21: 요율 | Q21: 수당
A22: 1 | B22: 2023042 | C22: 우현욱 | D22: - | E22: 이천HN_OP | F22: 휴일근로 | G22: 2026.05.01 | H22: 13 | I22: 13 | J22: 1.5 | K22: =I22*J22*R22 -> 214574.1 | R22: 11003.8 | S22: 214,574원
A24: * Sort :
A25: 1. Primary Key : 구분 오름차순 ( 연장/대체근로, 휴일근로)
A26: 2. Secondary Key : 직급순 ( 사용자 정의 : 부장,차장,과장,대리,사원 )
A27: 3. Third Key : 사번 오름차순
A28: 4. Fourth Key: 근무날짜 오름차순
A30: * 휴일근로수당 계산식
A31: 휴일근로수당 = (공)휴일근로시간 x 1.5 x 통상시급
A32: - 기존 스케줄근무표상에 휴일근로시 근로시간 * 1.5 로 책정하여 지급함 ( 연장과 야간근무수당은 이미 월급여에 반영됨 )
A34: * 연장근로수당(평일) 계산식
A35: 연장근로수당 = ( 연장근로시간 x 1.5 + 야간근로시간 x 2.0 ) x 통상시급
A36: 설명 : 연장근로수당 = (총연장근로시간 x 1.5 + 야간근로가산시간(야간근로시간 x 0.5)) x 통상시급
A37: - 단, 휴일 스케줄근무후 연장 근로를 하는 경우 휴일근로가산 0.5 가 추가되어야 함.
... A45: 설명 : 대체근로수당 = ((총근로시간 - 총연장근로시간) x 1.5 + 총연장근로시간 x 2.0 + 야간근로가산시간(야간근로시간 x 0.5)) x 통상시급

Sheet 검증_1
A1: 별첨1. DT사업1팀 교대근무자 시간외근로수당 내역 (2026년 4월)
A2: No. | B2: 사번 | C2: 성명 | D2: 직급 | E2: 단위 조직 | F2: 구분 | G2: 근무 날짜 | H2: 근무 시간 | I2: 기본시간 | J2: 기본요율 | K2: 기본수당 | L2: 연장시간 | M2: 연장요율 | N2: 연장수당 | O2: 야간시간 | P2: 야간요율 | Q2: 야간수당 | R2: 통상시급 | S2: 지급 비용 | U2: 인력현황 | V2: 시급 | W2: 지급비용
A3: 1 | B3: 2024023 | C3: 박건우 | D3: - | E3: SKB동작국사 | F3: 연장근무 | G3: 2026.04.02 | L3: 1 | M3: 1.5 | N3: =ROUND(L3*M3*R3,0) -> 16760 | R3: 11173.59 | S3: =ROUNDUP(K3+N3+Q3,0) -> 16760 | U3: =VLOOKUP(C3,[1]인력현황_202604!$F$2:$CD$213,56,FALSE) -> 11173.59 | V3: =R3=U3 -> TRUE | W3: =별첨1!S5=검증_1!S3 -> TRUE | AA3: 값
A4: 2 | B4: 2024023 | C4: 박건우 | D4: - | E4: SKB동작국사 | F4: 연장근무 | G4: 2026.04.02 | L4: 1 | M4: 1.5 | N4: =ROUND(L4*M4*R4,0) -> 16760 | R4: 11173.59 | S4: =ROUNDUP(K4+N4+Q4,0) -> 16760 | U4: =VLOOKUP(C4,[1]인력현황_202604!$F$2:$CD$213,56,FALSE) -> 11173.59 | V4: =R4=U4 -> TRUE | W4: =별첨1!S6=검증_1!S4 -> TRUE | Y4: 성명 | Z4: 단위 조직 | AA4: 합계 : 연장시간 | AB4: 합계 : 지급 비용
A5: 3 | B5: 2014102 | C5: 박성호 | D5: - | E5: SKB동작국사 | F5: 연장근무 | G5: 2026.04.03 | L5: 1 | M5: 1.5 | N5: =ROUND(L5*M5*R5,0) -> 19348 | R5: 12898.79 | S5: =ROUNDUP(K5+N5+Q5,0) -> 19348 | U5: =VLOOKUP(C5,[1]인력현황_202604!$F$2:$CD$213,56,FALSE) -> 12898.79 | V5: =R5=U5 -> TRUE | W5: =별첨1!S7=검증_1!S5 -> TRUE | Y5: 고현재 | Z5: SKB동작국사 | AA5: 4 | AB5: 68744
A6: 4 | B6: 2014102 | C6: 박성호 | D6: - | E6: SKB동작국사 | F6: 연장근무 | G6: 2026.04.03 | L6: 1 | M6: 1.5 | N6: =ROUND(L6*M6*R6,0) -> 19348 | R6: 12898.79 | S6: =ROUNDUP(K6+N6+Q6,0) -> 19348 | U6: =VLOOKUP(C6,[1]인력현황_202604!$F$2:$CD$213,56,FALSE) -> 12898.79 | V6: =R6=U6 -> TRUE | W6: =별첨1!S8=검증_1!S6 -> TRUE | Y6: 박건우 | Z6: SKB동작국사 | AA6: 2 | AB6: 33520
A7: 5 | B7: 2020091 | C7: 고현재 | D7: - | E7: SKB동작국사 | F7: 연장근무 | G7: 2026.04.10 | L7: 1 | M7: 1.5 | N7: =ROUND(L7*M7*R7,0) -> 17186 | R7: 11457.12 | S7: =ROUNDUP(K7+N7+Q7,0) -> 17186 | U7: =VLOOKUP(C7,[1]인력현황_202604!$F$2:$CD$213,56,FALSE) -> 11457.12 | V7: =R7=U7 -> TRUE | W7: =별첨1!S9=검증_1!S7 -> TRUE | Y7: 박성호 | Z7: SKB동작국사 | AA7: 2 | AB7: 38696
A8: 6 | B8: 2020091 | C8: 고현재 | D8: - | E8: SKB동작국사 | F8: 연장근무 | G8: 2026.04.10 | L8: 1 | M8: 1.5 | N8: =ROUND(L8*M8*R8,0) -> 17186 | R8: 11457.12 | S8: =ROUNDUP(K8+N8+Q8,0) -> 17186 | U8: =VLOOKUP(C8,[1]인력현황_202604!$F$2:$CD$213,56,FALSE) -> 11457.12 | V8: =R8=U8 -> TRUE | W8: =별첨1!S10=검증_1!S8 -> TRUE | Y8: 주향모 | Z8: SKB동작국사 | AA8: 2 | AB8: 36048
A9: 7 | B9: 2026011 | C9: 주향모 | D9: - | E9: SKB동작국사 | F9: 연장근무 | G9: 2026.04.24 | L9: 1 | M9: 1.5 | N9: =ROUND(L9*M9*R9,0) -> 18024 | R9: 12015.67 | S9: =ROUNDUP(K9+N9+Q9,0) -> 18024 | U9: =VLOOKUP(C9,[1]인력현황_202604!$F$2:$CD$213,56,FALSE) -> 12015.67 | V9: =R9=U9 -> TRUE | W9: =별첨1!S11=검증_1!S9 -> TRUE | Y9: 총합계 | AA9: 10 | AB9: 177008
A10: 8 | B10: 2026011 | C10: 주향모 | D10: - | E10: SKB동작국사 | F10: 연장근무 | G10: 2026.04.24 | L10: 1 | M10: 1.5 | N10: =ROUND(L10*M10*R10,0) -> 18024 | R10: 12015.67 | S10: =ROUNDUP(K10+N10+Q10,0) -> 18024 | U10: =VLOOKUP(C10,[1]인력현황_202604!$F$2:$CD$213,56,FALSE) -> 12015.67 | V10: =R10=U10 -> TRUE | W10: =별첨1!S12=검증_1!S10 -> TRUE
A11: 9 | B11: 2020091 | C11: 고현재 | D11: - | E11: SKB동작국사 | F11: 연장근무 | G11: 2026.04.30 | L11: 1 | M11: 1.5 | N11: =ROUND(L11*M11*R11,0) -> 17186 | R11: 11457.12 | S11: =ROUNDUP(K11+N11+Q11,0) -> 17186 | U11: =VLOOKUP(C11,[1]인력현황_202604!$F$2:$CD$213,56,FALSE) -> 11457.12 | V11: =R11=U11 -> TRUE | W11: =별첨1!S13=검증_1!S11 -> TRUE
A12: 10 | B12: 2020091 | C12: 고현재 | D12: - | E12: SKB동작국사 | F12: 연장근무 | G12: 2026.04.30 | L12: 1 | M12: 1.5 | N12: =ROUND(L12*M12*R12,0) -> 17186 | R12: 11457.12 | S12: =ROUNDUP(K12+N12+Q12,0) -> 17186 | U12: =VLOOKUP(C12,[1]인력현황_202604!$F$2:$CD$213,56,FALSE) -> 11457.12 | V12: =R12=U12 -> TRUE | W12: =별첨1!S14=검증_1!S12 -> TRUE
A13: - | B13: - | C13: 소 계 | D13: - | E13: - | F13: - | G13: - | L13: 10 | M13: - | N13: 177008 | O13: - | P13: - | Q13: - | R13: - | S13: 177008
A14: - | B14: - | C14: 합 계 | D14: - | E14: - | F14: 합계 | G14: - | L14: 10 | M14: - | N14: 177008 | O14: - | P14: - | Q14: - | R14: - | S14: 177008
A16: ※ 5월 퇴사자 조기 지급 내역
A17: No. | B17: 사번 | C17: 성명 | D17: 직급 | E17: 단위 조직 | F17: 구분 | G17: 근무 날짜 | H17: 근무 시간 | I17: 근로수당 현황 | R17: 통상시급 | S17: 지급 비용
I18: 기본 근로수당 | L18: 연장 근로수당 | O18: 야간 근로수당
I19: 시간 | J19: 요율 | K19: 수당 | L19: 시간 | M19: 요율 | N19: 수당 | O19: 시간 | P19: 요율 | Q19: 수당
A20: 1 | B20: 2023042 | C20: 우현욱 | D20: - | E20: 이천HN_OP | F20: 휴일근로 | G20: 2026.05.01 | H20: 13 | I20: 13 | J20: 1.5 | K20: =I20*J20*R20 -> 214574.1 | R20: 11003.8 | S20: 214,574원
A24: 1. 법정공휴일
A25: 법정공휴일, 공휴일, 휴일근로로 분류된 근무에 적용됩니다.
A26: 적용 요율: 2026.2 (2026.7.1 ~ 미정)
A27: 적용 배수: 기본 x1.5 / 연장 x1.5 / 야간 x1.5
A28: 계산식 1: 기본수당 = 시급 x 기본시간 x1.5
A29: 계산식 2: 연장수당 = 시급 x 연장시간 x1.5
A30: 계산식 3: 야간수당 = 시급 x 야간시간 x1.5
A32: 2. 평_대체근로수당
A33: 평일에 발생한 대체근무에 적용됩니다.
A34: 적용 요율: 2026.2 (2026.7.1 ~ 미정)
A35: 적용 배수: 기본 x1.5 / 연장 x2 / 야간 x2.5
A36: 계산식 1: 기본수당 = 시급 x 기본시간 x1.5
... A62: 계산식 3: 야간수당 = 시급 x 야간시간 x0

Sheet 인력현황_202604
A1: =TODAY() -> 46161 | B1: 0.209 | C1: 2026년 최저시급 | D1: 10320 | F1: 1 | G1: 2 | H1: 3 | I1: 4 | J1: 5 | K1: 6 | L1: 7 | M1: 8 | N1: 9 | O1: 10 | P1: 11 | Q1: 12 | R1: 13 | S1: 14 | T1: 15 | U1: 16 | V1: 17 | W1: 18 | X1: 19 | Y1: 20 | Z1: 21 | AA1: 22 | AB1: 23 | AC1: 24 | AD1: 25 | AE1: 26 | AF1: 27 | AG1: 28 | AH1: 29 | AI1: 30 | AJ1: 31 | AK1: 32 | AL1: 33 | AM1: 34 | AN1: 35 | AO1: 36 | AP1: 37 | AQ1: 38 | AR1: 39 | AS1: 40 | AT1: 41 | AU1: 42 | AV1: 43 | AW1: 44 | AX1: 45 | AY1: 46 | AZ1: 47 | BA1: 48 | BB1: 49 | BC1: 50 | BD1: 51 | BE1: 52 | BF1: 53 | BG1: 54 | BH1: 55 | BI1: 56 | BJ1: 57 | BK1: 58 | BL1: 59 | BM1: 60 | BN1: 61 | BO1: 62 | BP1: 63 | BQ1: 64 | BR1: 65 | BS1: 66 | BT1: 67 | BU1: 68 | BV1: 69 | BW1: 70 | BX1: 71 | BY1: 72 | BZ1: 73 | CA1: 74 | CB1: 75 | CC1: 76 | CD1: 77 | CE1: 78 | CF1: 79 | CG1: 80 | CH1: 81 | CI1: 82
A2: No. | B2: 개인정보제공 동의서 수령 | C2: 사원번호 | D2: 고객사담당자 | E2: 현장대리인 | F2: 성명 | G2: 직급 | H2: 기술등급 | I2: 계약등급 | J2: 계약형태 | K2: 직무명 | L2: 비고 | M2: 사무실 | N2: 핸드폰 | O2: e메일 | P2: 생년월일 | Q2: 경력기준일 | R2: 입사일1 | S2: 입사일2 (플러스 전환) | T2: 출신교 | U2: 전공학과 | V2: 최종학력 | W2: 자격증 1 | X2: 자격증2 | Y2: 자격증 3 | Z2: 총경력 | AA2: 근속기간 | AB2: 퇴사일 or 프리계약 종료일 | AC2: 퇴사사유 | AD2: 근무지1 | AE2: 근무지2_최종 | AF2: 2025 _사업분류 | AG2: 2026 _사업분류 | AH2: 매출처 | AI2: On-Site | AJ2: 의욕관리대상 | AK2: 우편번호 | AL2: 근무지주소(신) | AM2: 집우편번호 | AN2: 집주소(신) | AO2: 고객사소속팀 | AP2: Part | AQ2: 담당업무1 | AR2: 담당업무2 | AS2: 계약명/Pjt명 | AT2: 근무유형 | AU2: 소속구분 | AV2: 소속사 | AW2: 월매출단가_직전 | AX2: 월매출단가_현재 | AY2: M/M | AZ2: 년매출액 | BA2: 월외주비 _직전 | BB2: 월외주비 _현재 | BC2: 마지막 연봉 적용일 | BD2: 전전연봉 | BE2: 직전 연봉 | BF2: 현재 연봉_2026 | BG2: 월급여총액 | BH2: 기본급/월_신기준 | BI2: 통상시급 | BJ2: 기본급 구성시간 | BK2: 월 평균 고정 연장 근로시간 | BL2: 월 평균 고정 야간 근로시간 | BM2: 고정연장근로 가산수당 | BN2: 고정야간근로 가산수당 | BO2: 식대/월 | BP2: 원가B:년평균 휴일근로수당 | BQ2: 최저임금비교 | BR2: 비고 (기타지급/월) | BS2: 평균연차수당 (통상:5일기준, 스케줄:100시간기준) | BT2: 퇴직충당 | BU2: 국민연금 | BV2: `26_건강보험 (요양보험포함) | BW2: `26_고용보험(150~1,000미만) | BX2: `26_산재 보험 | BY2: 월인건비_원가 | BZ2: 직접인건비 | CA2: 간접인건비 | CB2: 원가A:인건비계(원가) (정직원:연봉의 1.25배 적용) | CC2: 연간매출이익 (매출액-원가A-원가B*1.21) | CD2: 매출이익률(%) | CE2: 청내공 _만료일 | CF2: 학자금 상환 개시일 | CG2: 채용경로 | CH2: 채용담당 | CI2: 장애인/ 국가유공자
D3: 류혜리 M | E3: 최재유 | H3: 중급상 | I3: 중급기술자 | J3: 유지보수(FTE) | K3: 응용프로그래머 | L3: 2019_신규 | N3: 010-8585-5281 | O3: atmnet@naver.com | P3: 761007-1 | Q3: 37304 | R3: 43586 | T3: 안동대학교 | U3: 정보통신공학과 | Z3: =IF(Q3<>"",$A$1-Q3,"") -> 8857 | AA3: =$A$1-R3 -> 2575 | AB3: 46387 | AF3: 2. Network Service | AG3: 2. Network Service | AH3: SK AX | AI3: SK그룹사(공통) | AK3: 13486 | AL3: 경기도 성남시 분당구 판교로 255번길 46 SK C&C 판교캠퍼스 A동 4층 | AM3: 14772 | AN3: 경기도 부천시 소사동로72번길 32 소새울역중흥S클래스아파트 409동 304호 | AO3: Network Service팀 | AP3: SK_NOBS MA | AQ3: 프로그램 개발 | AR3: 고객 요청 대응 | AS3: 고객사 공통 / 2026년_회선서비스1(4500303393-01) | AU3: 프리랜서 | AV3: 개인(사업소득) | AW3: 1500000 | AX3: 1500000 | AY3: 12 | AZ3: =AX3*AY3 -> 18000000 | BA3: 1000000 | BB3: 1000000 | BC3: 43586 | BW3: =IF((BB3-BB3*$B$1)<800000,"해당없음",ROUNDDOWN(IF(BB3-BB3*$B$1<1330000,1330000*0.016/2,(BB3-BB3*$B$1)*(0.016/2)),-1)) -> 해당없음 | BX3: =ROUNDDOWN((BB3-BB3*$B$1)*(0.28%),-1) -> 2210 | BY3: =BB3 -> 1000000 | CB3: =IF(BW3="해당없음", (BB3+BX3)*AY3, BB3*AY3+(BW3+BX3)*AY3) -> 12026520 | CC3: =AZ3-CB3 -> 5973480 | CD3: =IFERROR((CC3/AZ3)*100,0) -> 33.186
A4: 1 | C4: 2023501 | D4: 이성전 위원 | E4: 박규성 | F4: 김병호 | G4: 차장 | H4: 중급상 | I4: 중급기술자 | J4: 하도급(M/M) | K4: 네트워크엔지니어 | L4: 2023-01-11부 프리전환 | M4: 02-6266-2397 | N4: 010-9154-5103 | O4: howpc80@cnthoth.com | P4: 800810-1 | Q4: 37865 | R4: 44937 | T4: 북공고 | V4: 고졸 | W4: CCNA | X4: CCNP | Z4: =IF(Q4<>"",$A$1-Q4,"") -> 8296 | AA4: =$A$1-R4 -> 1224 | AB4: 46203 | AD4: SKB 7층_동작 | AE4: 서울특별시 | AF4: 4. SKB/SK하이닉스 Infra 운영 | AG4: 4. SKB/SK하이닉스 Infra 운영 | AH4: SK AX | AI4: SKB(동작) | AK4: 07063 | AL4: 서울시 동작구 여의대방로 74 (신대방동) SK브로드밴드 7층 | AM4: 01229 | AN4: 서울특별시 강북구 한천로 105길 24, 211동 1320호 (번동, 번동2단지주공아파트) | AO4: ICT Cloud팀 | AP4: SKB N/W 운영 | AQ4: L3 운영 | AS4: 에스케이브로드밴드(주) / SKB 26년 IT장비 및 소프트웨어 유지보수_1분기(4500302989-01) | AT4: 통상 | AU4: 프리랜서 | AV4: 개인(사업소득) | AW4: 6488000 | AX4: 6488000 | AY4: 12 | AZ4: =AX4*AY4 -> 77856000 | BA4: 4800000 | BB4: 4900000 | BC4: 45839 | BW4: =IF((BB4-BB4*$B$1)<800000,"해당없음",ROUNDDOWN(IF(BB4-BB4*$B$1<1330000,1330000*0.016/2,(BB4-BB4*$B$1)*(0.016/2)),-1)) -> 31000 | BX4: =ROUNDDOWN((BB4-BB4*$B$1)*(0.28%),-1) -> 10850 | BY4: =BB4 -> 4900000 | CB4: =BB4*AY4+(BW4+BX4)*AY4 -> 59302200 | CC4: =AZ4-CB4 -> 18553800 | CD4: =IFERROR((CC4/AZ4)*100,0) -> 23.830919
A5: =ROW()-3 -> 2 | D5: 김태형 M, 이범철 M | E5: 이규동 | F5: 이규동 | G5: 과장 | H5: 중급상 | I5: 중급기술자 | J5: 하도급(FTE) | K5: DBA | L5: 2023-08-08부 프리전환 | M5: 02-6400-8856 | N5: 010-7574-1133 | O5: puma7574@cnthoth.com | P5: 830710-1 | Q5: 40118 | R5: 45146 | T5: 성남서고등학교 | V5: 고졸 | Z5: =IF(Q5<>"",$A$1-Q5,"") -> 6043 | AA5: =$A$1-R5 -> 1015 | AB5: 46203 | AD5: 분당지웰푸르지오_수내 | AE5: 경기도 | AF5: 1. Infra 운영 | AG5: 1. Infra 운영 | AH5: SK AX | AI5: SK그룹사(공통) | AK5: 13594 | AL5: 경기도 성남시 분당구 수내로 39 분당지웰푸르지오아파트 오피스 6층 | AM5: 05849 | AN5: 서울특별시 송파구 위례광장로 170, 102동 401호 (장지동, 힐스테이트 송파위례) | AO5: T Biz. Cloud팀 | AP5: DB 운영 | AQ5: Oracle 운영 | AR5: 고객 요청 처리 | AS5: 고객사 공통 / 2026년_인프라운영_HC12_1분기(4500303380-01) | AT5: 통상 | AU5: 프리랜서 | AV5: 개인(사업소득) | AW5: 5989000 | AX5: 5989000 | AY5: 12 | AZ5: =AX5*AY5 -> 71868000 | BA5: 5100000 | BB5: 5200000 | BC5: 45839 | BW5: =IF((BB5-BB5*$B$1)<800000,"해당없음",ROUNDDOWN(IF(BB5-BB5*$B$1<1330000,1330000*0.016/2,(BB5-BB5*$B$1)*(0.016/2)),-1)) -> 32900 | BX5: =ROUNDDOWN((BB5-BB5*$B$1)*(0.28%),-1) -> 11510 | BY5: =BB5 -> 5200000 | CB5: =BB5*AY5+(BW5+BX5)*AY5 -> 62932920 | CC5: =AZ5-CB5 -> 8935080 | CD5: =IFERROR((CC5/AZ5)*100,0) -> 12.432626
A6: =ROW()-3 -> 3 | D6: 김정훈 M | E6: 하상국(임명:박현성) | F6: 박현성 | G6: 과장 | H6: 중급하 | I6: 중급기술자 | J6: 하도급(M/M) | K6: 네트워크엔지니어 | L6: 2023-10-01부 프리전환 | N6: 010-2037-1515 | O6: dortus535@cnthoth.com | P6: 861001-1 | Q6: 40299 | R6: 45200 | T6: 방송통신대학교 | U6: 컴퓨터학과 | V6: 대졸예정 | Z6: =IF(Q6<>"",$A$1-Q6,"") -> 5862 | AA6: =$A$1-R6 -> 961 | AB6: 46203 | AD6: SK AX A동 4F_판교 | AE6: 경기도 | AF6: 1. Infra 운영 | AG6: 1. Infra 운영 | AH6: SK AX | AI6: SKT(판교/SKT성수국사) | AK6: 35259 | AL6: 경기도 성남시 분당구 판교로 255번길 46 SK C&C 판교캠퍼스 A동 4층 | AM6: 06611 | AN6: 서울특별시 서초구 서초대로73길 54, 1412호 (서초동, 서초동 오피스텔) | AO6: Network Service팀 | AP6: SKT N/W 구축 및 MA | AQ6: 구축 및 유지보수 | AS6: 에스케이텔레콤(주) / SKT 25년 SDN IP장비 유지보수 용역계약_26년1분기 (4500302287-01) | AT6: 통상 | AU6: 프리랜서 | AV6: 개인(사업소득) | AW6: 5461000 | AX6: 5461000 | AY6: 12 | AZ6: =AX6*AY6 -> 65532000 | BA6: 4200000 | BB6: 4300000 | BC6: 45839 | BW6: =IF((BB6-BB6*$B$1)<800000,"해당없음",ROUNDDOWN(IF(BB6-BB6*$B$1<1330000,1330000*0.016/2,(BB6-BB6*$B$1)*(0.016/2)),-1)) -> 27210 | BX6: =ROUNDDOWN((BB6-BB6*$B$1)*(0.28%),-1) -> 9520 | BY6: =BB6 -> 4300000 | CB6: =BB6*AY6+(BW6+BX6)*AY6 -> 52040760 | CC6: =AZ6-CB6 -> 13491240 | CD6: =IFERROR((CC6/AZ6)*100,0) -> 20.587255
A7: =ROW()-3 -> 4 | B7: Yes | D7: 정명호 M | E7: 김교원 | F7: 김교원 | G7: 부장 | H7: 특급 | I7: 특급기술자 | J7: 하도급(M/M) | K7: PMO | L7: 2025-01-01부 프리전환 | N7: 010-5470-0657 | O7: gk03449@cnthoth.com | P7: 740212-1 | Q7: 34700 | R7: 45658 | T7: 동서울대학교 | U7: 전자계산학과 | V7: 전문대중퇴 | Z7: =IF(Q7<>"",$A$1-Q7,"") -> 11461 | AA7: =$A$1-R7 -> 503 | AB7: 46203 | AD7: SKB_수유 1F | AE7: 서울특별시 | AF7: 3. 콜센터 & 금융 & 기타 | AG7: 3. 콜센터 & 금융 & 기타 | AH7: SK AX | AI7: SKB(수유) | AK7: 01133 | AL7: 서울시 강북구 도봉로 238 1층 SKB 미디어운용센터 | AM7: 22142 | AN7: 인천광역시 미추홀구 주안로205번길 18, 202호 (주안동, 대명리츠빌) | AO7: ICT Cloud팀 | AQ7: PMO | AR7: PMO | AS7: 에스케이브로드밴드(주) / SKB '25년 미디어 통합 유지보수(4500301890-01) | AT7: 통상 | AU7: 프리랜서 | AV7: 개인(사업소득) | AW7: 12500000 | AX7: 12700000 | AY7: 12 | AZ7: =AX7*AY7 -> 152400000 | BA7: 10000000 | BB7: 10100000 | BC7: 46023 | BW7: =IF((BB7-BB7*$B$1)<800000,"해당없음",ROUNDDOWN(IF(BB7-BB7*$B$1<1330000,1330000*0.016/2,(BB7-BB7*$B$1)*(0.016/2)),-1)) -> 63910 | BX7: =ROUNDDOWN((BB7-BB7*$B$1)*(0.28%),-1) -> 22360 | BY7: =BB7 -> 10100000 | CB7: =BB7*AY7+(BW7+BX7)*AY7 -> 122235240 | CC7: =AZ7-CB7 -> 30164760 | CD7: =IFERROR((CC7/AZ7)*100,0) -> 19.79315
A8: =ROW()-3 -> 5 | B8: Yes | D8: 김정훈 M | E8: 하상국 | F8: 하상국 | G8: 부장 | H8: 중급하 | I8: 중급기술자 | J8: 하도급(M/M) | K8: 네트워크엔지니어 | L8: 2025-04-01부 프리전환 | N8: 010-5353-0680 | O8: alina75@cnthoth.com | P8: 750529-1 | Q8: 37561 | R8: 45748 | T8: 동서울대학교 | U8: 컴퓨터소프트웨어과 | V8: 전문대졸 | Z8: =IF(Q8<>"",$A$1-Q8,"") -> 8600 | AA8: =$A$1-R8 -> 413 | AB8: 46203 | AD8: SK AX_판교 B동 | AE8: 경기도 | AF8: 1. Infra 운영 | AG8: 1. Infra 운영 | AH8: SK AX | AI8: SKT(판교/SKT성수국사) | AK8: 13486 | AL8: 경기도 성남시 분당구 판교로 255번길 46 SK C&C 판교캠퍼스 A동 4층 | AM8: 11939 | AN8: 경기도 구리시 체육관로 69, 201동 304호 (교문동, 하나아파트) | AO8: Network Service팀 | AP8: SKT N/W 구축 및 MA | AQ8: 구축 및 유지보수 | AS8: 에스케이텔레콤(주) / SKT 25년 SDN IP장비 유지보수 용역계약_26년1분기 (4500302287-01) | AT8: 통상 | AU8: 프리랜서 | AV8: 개인(사업소득) | AW8: 5674000 | AX8: 5674000 | AY8: 12 | AZ8: =AX8*AY8 -> 68088000 | BA8: 4700000 | BB8: 4850000 | BC8: 46023 | BW8: =IF((BB8-BB8*$B$1)<800000,"해당없음",ROUNDDOWN(IF(BB8-BB8*$B$1<1330000,1330000*0.016/2,(BB8-BB8*$B$1)*(0.016/2)),-1)) -> 30690 | BX8: =ROUNDDOWN((BB8-BB8*$B$1)*(0.28%),-1) -> 10740 | BY8: =BB8 -> 4850000 | CB8: =BB8*AY8+(BW8+BX8)*AY8 -> 58697160 | CC8: =AZ8-CB8 -> 9390840 | CD8: =IFERROR((CC8/AZ8)*100,0) -> 13.79221
A9: =ROW()-3 -> 6 | C9: 2026501 | D9: 지수환 M, 김도현 M | E9: 이경호 | F9: 이경호 | G9: 차장 | H9: 중급상 | I9: 중급기술자 | J9: 하도급(M/M) | K9: DBA | L9: 홍민지 후임 | N9: 010-2695-6654 | P9: 800117-1 | Q9: 40183 | R9: 46027 | T9: 성공회대학교 | U9: 전산정보공학과 | V9: 대졸 | W9: SQL개발자 | X9: OCP | Y9: 정보처리기사 외 | Z9: =IF(Q9<>"",$A$1-Q9,"") -> 5978 | AA9: =$A$1-R9 -> 134 | AB9: 46387 | AD9: 파라다이스_퇴계로 | AE9: 서울특별시 | AF9: 3. 콜센터 & 금융 & 기타 | AG9: 3. 콜센터 & 금융 & 기타 | AH9: SK AX | AI9: 파라다이스ITO | AJ9: 본사 관리 | AK9: 04560 | AL9: 서울시 중구 퇴계로 299 파라다이스 빌딩 7층 | AM9: 06937 | AN9: 서울특별시 동작구 상도로15길 131, 601호 (상도동, 상도 휴엔하임) | AO9: Cloud서비스 2팀 | AP9: 파라다이스 ITO | AQ9: DB 운영 | AS9: 고객사 공통 2026년_대외운영3(4500303729-01) | AT9: 통상 | AU9: 프리랜서 | AV9: 개인(사업소득) | AW9: 6700000 | AX9: 6700000 | AY9: 12 | AZ9: =AX9*AY9 -> 80400000 | BB9: 5500000 | BC9: 46023 | BW9: =IF((BB9-BB9*$B$1)<800000,"해당없음",ROUNDDOWN(IF(BB9-BB9*$B$1<1330000,1330000*0.016/2,(BB9-BB9*$B$1)*(0.016/2)),-1)) -> 34800 | BX9: =ROUNDDOWN((BB9-BB9*$B$1)*(0.28%),-1) -> 12180 | BY9: =BB9 -> 5500000 | CB9: =BB9*AY9+(BW9+BX9)*AY9 -> 66563760 | CC9: =AZ9-CB9 -> 13836240 | CD9: =IFERROR((CC9/AZ9)*100,0) -> 17.209254 | CH9: 이민호
A10: =ROW()-3 -> 7 | B10: Yes | C10: 2026502 | D10: 신항범M | E10: 이정민77 | F10: 이정민77 | G10: 부장 | H10: 고급상 | I10: 고급기술자 | J10: 하도급(M/M) | K10: 서버엔지니어 | L10: 2026_신규 | N10: 010-3769-1325 | O10: nin1325@cnthoth.com | P10: 771227-1 | R10: 46097 | T10: 대건고등학교 | V10: 고졸 | W10: RHCSA | Z10: =IF(Q10<>"",$A$1-Q10,"") | AA10: =$A$1-R10 -> 64 | AB10: 46310 | AD10: SK하이닉스_충칭 | AE10: 중국 | AG10: 5. 신규사업 | AH10: SK AX | AI10: SK하이닉스(충칭) | AM10: 22835 | AN10: 인천광역시 서구 염곡로 128-7, 3동 102호 (가좌동, 한일빌라) | AO10: Hynix Cloud팀 | AP10: SK하이닉스_충칭 DR 구축 | AQ10: 윈도우 서버 구축 | AT10: 통상 | AU10: 프리랜서 | AV10: 개인(사업소득) | AX10: 10000000 | AY10: 7 | AZ10: =AX10*AY10 -> 70000000 | BB10: 8500000 | BC10: 46097 | BW10: =IF((BB10-BB10*$B$1)<800000,"해당없음",ROUNDDOWN(IF(BB10-BB10*$B$1<1330000,1330000*0.016/2,(BB10-BB10*$B$1)*(0.016/2)),-1)) -> 53780 | BX10: =ROUNDDOWN((BB10-BB10*$B$1)*(0.28%),-1) -> 18820 | BY10: =BB10 -> 8500000 | CB10: =BB10*AY10+(BW10+BX10)*AY10 -> 60008200 | CC10: =AZ10-CB10 -> 9991800 | CD10: =IFERROR((CC10/AZ10)*100,0) -> 14.274 | CH10: 이민호
A11: =ROW()-3 -> 8 | B11: Yes | C11: 2026503 | D11: 신항범M | E11: 이정민 | F11: 전원식 | G11: 부장 | H11: 고급상 | I11: 고급기술자 | J11: 하도급(M/M) | K11: 서버엔지니어 | L11: 2026_신규 | N11: 010-3692-7469 | O11: wsjeon@cnthoth.com | P11: 740221-1 | R11: 46113 | T11: 서울보건대학 | U11: 전산정보처리 | V11: 전문대졸 | W11: MCDBA | Z11: =IF(Q11<>"",$A$1-Q11,"") | AA11: =$A$1-R11 -> 48 | AB11: 46326 | AD11: SK하이닉스_충칭 | AE11: 중국 | AG11: 5. 신규사업 | AH11: SK AX | AI11: SK하이닉스(충칭) | AM11: 30098 | AN11: 세종특별자치시 보듬4로 20, 도램마을10단지 1001동 702호 | AO11: Hynix Cloud팀 | AP11: SK하이닉스_충칭 DR 구축 | AQ11: 리눅스 서버 구축 | AT11: 통상 | AU11: 프리랜서 | AV11: 개인(사업소득) | AX11: 10000000 | AY11: 7 | AZ11: =AX11*AY11 -> 70000000 | BB11: 8500000 | BW11: =IF((BB11-BB11*$B$1)<800000,"해당없음",ROUNDDOWN(IF(BB11-BB11*$B$1<1330000,1330000*0.016/2,(BB11-BB11*$B$1)*(0.016/2)),-1)) -> 53780 | BX11: =ROUNDDOWN((BB11-BB11*$B$1)*(0.28%),-1) -> 18820 | BY11: =BB11 -> 8500000 | CB11: =BB11*AY11+(BW11+BX11)*AY11 -> 60008200 | CC11: =AZ11-CB11 -> 9991800 | CD11: =IFERROR((CC11/AZ11)*100,0) -> 14.274 | CG11: 잡코리아 | CH11: 이민호
A12: =ROW()-3 -> 9 | B12: Yes | C12: 2026504 | D12: 신항범M | E12: 이정민 | F12: 허근호 | G12: 부장 | H12: 고급상 | I12: 고급기술자 | J12: 하도급(M/M) | K12: Backup/Storage 엔지니어 | L12: 2026_신규 | N12: 010-5477-8284 | O12: khhuh@cnthoth.com | P12: 751023-1 | R12: 46113 | T12: 명지대학교 | U12: 화학공학과 | V12: 대졸 | Z12: =IF(Q12<>"",$A$1-Q12,"") | AA12: =$A$1-R12 -> 48 | AB12: 46295 | AD12: SK하이닉스_충칭 | AE12: 중국 | AG12: 5. 신규사업 | AH12: SK AX | AI12: SK하이닉스(충칭) | AM12: 12924 | AN12: 경기도 하남시 미사강변중앙로 90, 101동 2602호 (풍산동, 이편한세상미사) | AO12: Hynix Cloud팀 | AP12: SK하이닉스_충칭 DR 구축 | AQ12: 스토리지 구축 | AT12: 통상 | AU12: 프리랜서 | AV12: 개인(사업소득) | AX12: 10000000 | AY12: 6 | AZ12: =AX12*AY12 -> 60000000 | BB12: 8500000 | BW12: =IF((BB12-BB12*$B$1)<800000,"해당없음",ROUNDDOWN(IF(BB12-BB12*$B$1<1330000,1330000*0.016/2,(BB12-BB12*$B$1)*(0.016/2)),-1)) -> 53780 | BX12: =ROUNDDOWN((BB12-BB12*$B$1)*(0.28%),-1) -> 18820 | BY12: =BB12 -> 8500000 | CB12: =BB12*AY12+(BW12+BX12)*AY12 -> 51435600 | CC12: =AZ12-CB12 -> 8564400 | CD12: =IFERROR((CC12/AZ12)*100,0) -> 14.274 | CG12: 잡코리아 | CH12: 이민호
A13: =ROW()-3 -> 10 | B13: Yes | C13: 2026505 | D13: 전성민M | E13: 이은서 | F13: 이경원 | G13: 부장 | H13: 고급상 | I13: 고급기술자 | J13: 하도급(M/M) | K13: M/W 엔지니어 | L13: 2026_추가 | N13: 010-4398-0824 | O13: campione20@naver.com | P13: 731015-1 | R13: 46113 | T13: 단국대(천안) | U13: 전자계산학과 | V13: 대졸 | W13: 정보처리기사 | Z13: =IF(Q13<>"",$A$1-Q13,"") | AA13: =$A$1-R13 -> 48 | AD13: SK하이닉스_이천 | AE13: 경기도 | AG13: 4. SKB/SK하이닉스 Infra 운영 | AH13: SK AX | AI13: SK하이닉스(이천) | AM13: 04321 | AN13: 서울특별시 용산구 한강대로87길 7-8, 202호 (갈월동) | AO13: Hynix Cloud팀 | AP13: SK하이닉스 인프라 운영 | AQ13: 미들웨어 운영 | AT13: 통상 | AU13: 프리랜서 | AV13: 개인(사업소득) | AX13: 8950000 | AY13: 12 | AZ13: =AX13*AY13 -> 107400000 | BB13: 7500000 | BW13: =IF((BB13-BB13*$B$1)<800000,"해당없음",ROUNDDOWN(IF(BB13-BB13*$B$1<1330000,1330000*0.016/2,(BB13-BB13*$B$1)*(0.016/2)),-1)) -> 47460 | BX13: =ROUNDDOWN((BB13-BB13*$B$1)*(0.28%),-1) -> 16610 | BY13: =BB13 -> 7500000 | CB13: =BB13*AY13+(BW13+BX13)*AY13 -> 90768840 | CC13: =AZ13-CB13 -> 16631160 | CD13: =IFERROR((CC13/AZ13)*100,0) -> 15.485251 | CG13: 잡코리아 | CH13: 이민호
A14: =ROW()-3 -> 11 | B14: Yes | C14: 2026506 | D14: 전성민M/신상선M | E14: 이은서 | F14: 양재훈 | G14: 부장 | H14: 고급상 | I14: 고급기술자 | J14: 하도급(M/M) | K14: 시스템엔지니어 | L14: 2026_추가 | N14: 010-9029-1709 | O14: jay2248@naver.com | P14: 690110-1 | R14: 46113 | T14: 경희대학교 | U14: 전산공학 | V14: 대졸 | W14: CCNA | X14: Ennterprise Architecture Professional | Y14: Microsoft Aure Fundamentlals | Z14: =IF(Q14<>"",$A$1-Q14,"") | AA14: =$A$1-R14 -> 48 | AD14: SK하이닉스_이천 | AE14: 경기도 | AG14: 4. SKB/SK하이닉스 Infra 운영 | AH14: SK AX | AI14: SK하이닉스(이천) | AM14: 04419 | AN14: 서울특별시 용산구 한남대로 60, 7층 A-709호 (한남동, 금호리첸시아) | AO14: Hynix Cloud팀 | AP14: SK하이닉스 인프라 구축 | AQ14: 용인 DC 구축 TA | AT14: 통상 | AU14: 프리랜서 | AV14: 개인(사업소득) | AX14: 10000000 | AY14: 12 | AZ14: =AX14*AY14 -> 120000000 | BB14: 8500000 | BW14: =IF((BB14-BB14*$B$1)<800000,"해당없음",ROUNDDOWN(IF(BB14-BB14*$B$1<1330000,1330000*0.016/2,(BB14-BB14*$B$1)*(0.016/2)),-1)) -> 53780 | BX14: =ROUNDDOWN((BB14-BB14*$B$1)*(0.28%),-1) -> 18820 | BY14: =BB14 -> 8500000 | CB14: =BB14*AY14+(BW14+BX14)*AY14 -> 102871200 | CC14: =AZ14-CB14 -> 17128800 | CD14: =IFERROR((CC14/AZ14)*100,0) -> 14.274 | CG14: 이민호 | CH14: 이민호
A15: =ROW()-3 -> 12 | C15: 2021701 | D15: 강윤선 M | E15: 김진욱 | F15: 김진욱 | G15: 차장 | H15: 중급상 | I15: 중급기술자 | J15: 하도급(M/M) | K15: 네트워크엔지니어 | L15: 2021_신규 | N15: 010-2118-3563 | O15: jwkim82@cnthoth.com | P15: 821128-1 | Q15: 40544 | R15: 44348 | T15: 경기공업대학교 | U15: 컴퓨터응용제어공학 | V15: 대졸 | W15: CCNA | X15: CCNP | Y15: CCDA | Z15: 5316 | AA15: =$A$1-R15 -> 1813 | AB15: 46112 | AD15: 분당두산타워_정자 | AE15: 경기도 | AF15: 3. 콜센터 & 금융 & 기타 | AG15: 3. 콜센터 & 금융 & 기타 | AH15: SK AX | AI15: SK하이닉스 | AK15: 13558 | AL15: 경기도 성남시 분당구 정자일로 155 분당두산타워 4층 | AM15: 16875 | AN15: 경기도 용인시 수지구 현암로 125번길 11, 새터마을죽전힐스테이트 722-102호 | AO15: Hynix Cloud팀 | AP15: SK하이닉스 네트워크/교환기 | AQ15: 네트워크 운영 | AR15: 화상회의 시스템, 교환기 등 | AS15: 에스케이하이닉스 주식회사 / 26년 Hynix SW개발센터 운영_1분기(4500302431-01) | AT15: 외주_통상 | AU15: 협력사 | AV15: ㈜인노인 | AW15: 6306000 | AX15: 6306000 | AY15: 12 | AZ15: =AX15*AY15 -> 75672000 | BA15: 5880000 | BB15: 6000000 | BC15: 45839 | BY15: =CB15/AY15 -> 6000000 | CB15: =AY15*BB15 -> 72000000 | CC15: =AZ15-CB15 -> 3672000 | CD15: =IFERROR((CC15/AZ15)*100,0) -> 4.8525214
A16: =ROW()-3 -> 13 | C16: 2025042 | D16: 양동식 M | E16: 김성구 | F16: 최종수 | G16: 사원 | H16: 고능 | I16: 고급기능사 | J16: 하도급(M/M) | K16: 서비스 관제 엔지니어 | L16: Pool | M16: 02-6400-5026 | N16: 010-9740-6321 | O16: js9876@cnthoth.com | P16: 960828-1 | Q16: 45873 | R16: 45873 | T16: 가톨릭대학교 | U16: 정보통신전자공학부 | V16: 대졸 | W16: SQLD | X16: 네트워크관리사2급 | Z16: =IF(Q16<>"",$A$1-Q16,"") -> 288 | AA16: =$A$1-R16 -> 288 | AD16: 판교DC | AE16: 경기도 | AF16: 1. Infra 운영 | AG16: 1. Infra 운영 | AH16: SK AX | AI16: SK그룹사(공통) | AJ16: 김성구 | AK16: 13486 | AL16: 경기도 성남시 분당구 판교로 255번길 46 SK(주) C&C 판교캠퍼스 A동 1층 | AM16: 07975 | AN16: 서울특별시 양천구 목동중앙본로20길 20, 파인빌 102호 (목동, 목동다세대주택) | AO16: CloudControlCenter팀 | AP16: 판교 DC 운영 | AQ16: H/W 육안점검, 시스템 모니터링 및 장애 전파 | AT16: 스케줄 | AU16: 정직원 | AV16: 씨앤토트플러스㈜ | AW16: 0 | AX16: 0 | AY16: 12 | AZ16: =AX16*AY16 -> 0 | BC16: 46023 | BE16: 27498000 | BF16: =BG16*12 -> 28203600 | BG16: =BH16+BM16+BN16+BO16 -> 2350300 | BH16: 1699000 | BI16: =ROUND((BH16+BO16)/BJ16,2) -> 10320.65 | BJ16: =IF(AT16="통상",209,VLOOKUP(AD16,'[2]스케줄 분석_20260109'!$B$3:$F$20,5,FALSE)) -> 184 | BK16: =IF(AT16="통상",15,VLOOKUP(AD16,'[2]스케줄 분석_20260109'!$B$3:$P$20,10,FALSE)) -> 38.02 | BL16: =IF(AT16="통상",0,VLOOKUP(AD16,'[2]스케줄 분석_20260109'!$B$3:$P$20,11,FALSE)) -> 49.43 | BM16: =IF(OR(AT16="통상",AT16="스케줄_파라"),ROUNDUP(BI16*BK16*1.5,-2),IF(OR(AT16="스케줄",AT16="휴직_스케줄"),ROUNDUP(BI16*BK16*0.5,-2),"확인바람")) -> 196200 | BN16: =ROUNDUP(BI16*BL16*0.5,-2) -> 255100 | BO16: 200000 | BP16: =IF(OR(AT16="스케줄",AT16="스케줄_파라"),ROUNDUP(VLOOKUP(AD16,'[2]스케줄 분석_20260109'!$B$3:$Y$20,23,FALSE)*(VLOOKUP(AD16,'[2]스케줄 분석_20260109'!$B$3:$Y$20,21,FALSE)/VLOOKUP(AD16,'[2]스케줄 분석_20260109'!$B$3:$Y$20,20,FALSE))*VLOOKUP(AD16,'[2]스케줄 분석_20260109'!$B$3:$Y$20,22,FALSE)*VLOOKUP(AD16,'[2]스케줄 분석_20260109'!$B$3:$Y$20,2,FALSE)*1.5*BI16,0),0) -> 1869328 | BQ16: =IF(BI16>=$D$1,"적합","미달") -> 적합 | BS16: =IF(AT16="통상",BI16*8*5,IF(OR(AT16="스케줄",AT16="스케줄_파라"),BI16*100,"확인")) -> 1032065 | BT16: =BG16+BS16/12 -> 2436305.4 | BU16: =(BF16-BO16*12)*0.0475 -> 1225671 | BV16: =(BF16-BO16*12)*0.036+(BF16-BO16*12)*0.036*0.1314 -> 1050990.9 | BW16: =(BF16-BO16*12)*(0.009+0.0065) -> 399955.8 | BX16: =(BF16-BO16*12)*0.0066 -> 170303.76 | BY16: =CB16/AY16 -> 2937875 | BZ16: =SUM(BF16,BS16:BT16) -> 31671970 | CA16: =SUM(BU16:BX16) -> 2846921.5 | CB16: =BF16*1.25 -> 35254500 | CC16: =AZ16-CB16-BP16*1.21 -> -37516387 | CD16: =IFERROR((CC16/AZ16)*100,0) -> 0 | CG16: 사람인 | CH16: 장소영
A17: =ROW()-3 -> 14 | B17: Yes | C17: 2014006 | D17: 양동식 M | E17: 김성구 | F17: 김성구 | G17: 부장 | H17: 고급상 | I17: 고급기술자 | J17: 하도급(M/M) | K17: 서비스 관제 센터장 | M17: 02-6400-5026 | N17: 010-4095-7792 | O17: skkim@cnthoth.com | P17: 721222-1 | Q17: 33725 | R17: 40613 | S17: 41640 | T17: 서울강동고등학교 | V17: 고졸 | Z17: =IF(Q17<>"",$A$1-Q17,"") -> 12436 | AA17: =$A$1-R17 -> 5548 | AD17: 판교DC_주간 | AE17: 경기도 | AF17: 1. Infra 운영 | AG17: 1. Infra 운영 | AH17: SK AX | AI17: SK그룹사(공통) | AJ17: 김성구 | AK17: 13486 | AL17: 경기도 성남시 분당구 판교로 255번길 46 SK(주) C&C 판교캠퍼스 A동 1층 | AM17: 10494 | AN17: 경기도 고양시 덕양구 중앙로 558번길 57, 1818동 203호 (행신동, 햇빛마을18단지아파트) | AO17: CloudControlCenter팀 | AP17: 판교 DC 운영 | AQ17: 센터 총괄 운영 | AS17: 고객사 공통 / 2026년_VDI_01_1분기(4500302906-01) | AT17: 통상 | AU17: 정직원 | AV17: 씨앤토트플러스㈜ | AW17: 8160000 | AX17: 8160000 | AY17: 12 | AZ17: =AX17*AY17 -> 97920000 | BC17: 45839 | BD17: 70848000 | BE17: 73248000 | BF17: =BG17*12 -> 73248000 | BG17: =BH17+BM17+BN17+BO17 -> 6104000 | BH17: 5310700 | BI17: =ROUND((BH17+BO17)/BJ17,2) -> 26366.99 | BJ17: =IF(AT17="통상",209,VLOOKUP(AD17,'[2]스케줄 분석_20260109'!$B$3:$F$20,5,FALSE)) -> 209 | BK17: =IF(AT17="통상",15,VLOOKUP(AD17,'[2]스케줄 분석_20260109'!$B$3:$P$20,10,FALSE)) -> 15 | BL17: =IF(AT17="통상",0,VLOOKUP(AD17,'[2]스케줄 분석_20260109'!$B$3:$P$20,11,FALSE)) -> 0 | BM17: =IF(OR(AT17="통상",AT17="스케줄_파라"),ROUNDUP(BI17*BK17*1.5,-2),IF(OR(AT17="스케줄",AT17="휴직_스케줄"),ROUNDUP(BI17*BK17*0.5,-2),"확인바람")) -> 593300 | BN17: =ROUNDUP(BI17*BL17*0.5,-2) -> 0 | BO17: 200000 | BP17: =IF(OR(AT17="스케줄",AT17="스케줄_파라"),ROUNDUP(VLOOKUP(AD17,'[2]스케줄 분석_20260109'!$B$3:$Y$20,23,FALSE)*(VLOOKUP(AD17,'[2]스케줄 분석_20260109'!$B$3:$Y$20,21,FALSE)/VLOOKUP(AD17,'[2]스케줄 분석_20260109'!$B$3:$Y$20,20,FALSE))*VLOOKUP(AD17,'[2]스케줄 분석_20260109'!$B$3:$Y$20,22,FALSE)*VLOOKUP(AD17,'[2]스케줄 분석_20260109'!$B$3:$Y$20,2,FALSE)*1.5*BI17,0),0) -> 0 | BQ17: =IF(BI17>=$D$1,"적합","미달") -> 적합 | BS17: =IF(AT17="통상",BI17*8*5,IF(OR(AT17="스케줄",AT17="스케줄_파라"),BI17*100,"확인")) -> 1054679.6 | BT17: =BG17+BS17/12 -> 6191890 | BU17: =(BF17-BO17*12)*0.0475 -> 3365280 | BV17: =(BF17-BO17*12)*0.036+(BF17-BO17*12)*0.036*0.1314 -> 2885667.4 | BW17: =(BF17-BO17*12)*(0.009+0.0065) -> 1098144 | BX17: =(BF17-BO17*12)*0.0066 -> 467596.8 | BY17: =CB17/AY17 -> 7630000 | BZ17: =SUM(BF17,BS17:BT17) -> 80494570 | CA17: =SUM(BU17:BX17) -> 7816688.2 | CB17: =BF17*1.25 -> 91560000 | CC17: =AZ17-CB17-BP17*1.21 -> 6360000 | CD17: =IFERROR((CC17/AZ17)*100,0) -> 6.495098
A18: =ROW()-3 -> 15 | B18: Yes | C18: 2014010 | D18: 박귀진 M, 유석민 M | E18: 이기홍 | F18: 이기홍 | G18: 부장 | H18: 고급하 | I18: 중급기술자 | J18: 하도급(FTE) | K18: IT Facility 매니저 | M18: 02-6343-9321 | N18: 010-5327-0922 | O18: skymonst@cnthoth.com | P18: 630725-1 | Q18: 33664 | R18: 45139 | T18: 안양과학대학 | V18: 전문대졸 | Z18: =IF(Q18<>"",$A$1-Q18,"") -> 12497 | AA18: =$A$1-R18 -> 1022 | AD18: SKT장안국사_주간 | AE18: 서울특별시 | AF18: 3. 콜센터 & 금융 & 기타 | AG18: 3. 콜센터 & 금융 & 기타 | AH18: SK AX | AI18: SKT(장안콜센터) | AJ18: 이기홍 | AK18: 02635 | AL18: 서울시 동대문구 장한로3길 34 SKT 장안고객센터 구관 2층 시스템 운영실 | AM18: 15875 | AN18: 경기도 군포시 용호2로 51, 101동 404호 (당동, 쌍용아파트) | AO18: T Biz. Cloud팀 | AP18: SKT_장안 시스템 운영 | AQ18: Facility 운영 | AR18: / 시스템 관제 관리 | AS18: 고객사 공통 / 2026년_ICT운영171_1분기(4500303362-01) | AT18: 통상 | AU18: 정직원 | AV18: 씨앤토트플러스㈜ | AW18: 6598000 | AX18: 6598000 | AY18: 12 | AZ18: =AX18*AY18 -> 79176000 | BC18: 45839 | BD18: 54444000 | BE18: 55644000 | BF18: =BG18*12 -> 55644000 | BG18: =BH18+BM18+BN18+BO18 -> 4637000 | BH18: 3986300 | BI18: =ROUND((BH18+BO18)/BJ18,2) -> 20030.14 | BJ18: =IF(AT18="통상",209,VLOOKUP(AD18,'[2]스케줄 분석_20260109'!$B$3:$F$20,5,FALSE)) -> 209 | BK18: =IF(AT18="통상",15,VLOOKUP(AD18,'[2]스케줄 분석_20260109'!$B$3:$P$20,10,FALSE)) -> 15 | BL18: =IF(AT18="통상",0,VLOOKUP(AD18,'[2]스케줄 분석_20260109'!$B$3:$P$20,11,FALSE)) -> 0 | BM18: =IF(OR(AT18="통상",AT18="스케줄_파라"),ROUNDUP(BI18*BK18*1.5,-2),IF(OR(AT18="스케줄",AT18="휴직_스케줄"),ROUNDUP(BI18*BK18*0.5,-2),"확인바람")) -> 450700 | BN18: =ROUNDUP(BI18*BL18*0.5,-2) -> 0 | BO18: 200000 | BP18: =IF(OR(AT18="스케줄",AT18="스케줄_파라"),ROUNDUP(VLOOKUP(AD18,'[2]스케줄 분석_20260109'!$B$3:$Y$20,23,FALSE)*(VLOOKUP(AD18,'[2]스케줄 분석_20260109'!$B$3:$Y$20,21,FALSE)/VLOOKUP(AD18,'[2]스케줄 분석_20260109'!$B$3:$Y$20,20,FALSE))*VLOOKUP(AD18,'[2]스케줄 분석_20260109'!$B$3:$Y$20,22,FALSE)*VLOOKUP(AD18,'[2]스케줄 분석_20260109'!$B$3:$Y$20,2,FALSE)*1.5*BI18,0),0) -> 0 | BQ18: =IF(BI18>=$D$1,"적합","미달") -> 적합 | BS18: =IF(AT18="통상",BI18*8*5,IF(OR(AT18="스케줄",AT18="스케줄_파라"),BI18*100,"확인")) -> 801205.6 | BT18: =BG18+BS18/12 -> 4703767.1 | BU18: =(BF18-BO18*12)*0.0475 -> 2529090 | BV18: =(BF18-BO18*12)*0.036+(BF18-BO18*12)*0.036*0.1314 -> 2168649.4 | BW18: =(BF18-BO18*12)*(0.009+0.0065) -> 825282 | BX18: =(BF18-BO18*12)*0.0066 -> 351410.4 | BY18: =CB18/AY18 -> 5796250 | BZ18: =SUM(BF18,BS18:BT18) -> 61148973 | CA18: =SUM(BU18:BX18) -> 5874431.8 | CB18: =BF18*1.25 -> 69555000 | CC18: =AZ18-CB18-BP18*1.21 -> 9621000 | CD18: =IFERROR((CC18/AZ18)*100,0) -> 12.15141
A19: =ROW()-3 -> 16 | B19: Yes | C19: 2014013 | D19: 김현수 M | E19: 최재유 | F19: 최재유 | G19: 부장 | H19: 고급상 | I19: 고급기술자 | J19: 하도급(FTE) | K19: 네트워크엔지니어 | M19: 02-6400-6080 | N19: 010-3781-9230 | O19: pelikan.ju@cnthoth.com | P19: 690507-1 | Q19: 32964 | R19: 40613 | S19: 41640 | T19: 강남대학교 | V19: 대졸 | Z19: =IF(Q19<>"",$A$1-Q19,"") -> 13197 | AA19: =$A$1-R19 -> 5548 | AD19: SK AX B동 4F_판교 | AE19: 경기도 | AF19: 2. Network Service | AG19: 2. Network Service | AH19: SK AX | AI19: SK그룹사(공통) | AJ19: 최재유 | AK19: 13486 | AL19: 경기도 성남시 분당구 판교로 255번길 38 SK C&C 판교캠퍼스 B동 4층 | AM19: 13436 | AN19: 경기도 성남시 중원구 성남대로 1000, 318동 101호 (여수동, 센트럴타운 3단지) | AO19: Network Service팀 | AP19: SK공통 N/W 보안 운영 | AQ19: NW 일반 운영 및 회선관리 | AS19: 고객사 공통 / 2026년_인프라운영_HC11_1분기(4500303149-01) | AT19: 통상 | AU19: 정직원 | AV19: 씨앤토트플러스㈜ | AW19: 7355000 | AX19: 7355000 | AY19: 12 | AZ19: =AX19*AY19 -> 88260000 | BC19: 45839 | BD19: 65040000 | BE19: 66480000 | BF19: =BG19*12 -> 66480000 | BG19: =BH19+BM19+BN19+BO19 -> 5540000 | BH19: 4801500 | BI19: =ROUND((BH19+BO19)/BJ19,2) -> 23930.62 | BJ19: =IF(AT19="통상",209,VLOOKUP(AD19,'[2]스케줄 분석_20260109'!$B$3:$F$20,5,FALSE)) -> 209 | BK19: =IF(AT19="통상",15,VLOOKUP(AD19,'[2]스케줄 분석_20260109'!$B$3:$P$20,10,FALSE)) -> 15 | BL19: =IF(AT19="통상",0,VLOOKUP(AD19,'[2]스케줄 분석_20260109'!$B$3:$P$20,11,FALSE)) -> 0 | BM19: =IF(OR(AT19="통상",AT19="스케줄_파라"),ROUNDUP(BI19*BK19*1.5,-2),IF(OR(AT19="스케줄",AT19="휴직_스케줄"),ROUNDUP(BI19*BK19*0.5,-2),"확인바람")) -> 538500 | BN19: =ROUNDUP(BI19*BL19*0.5,-2) -> 0 | BO19: 200000 | BP19: =IF(OR(AT19="스케줄",AT19="스케줄_파라"),ROUNDUP(VLOOKUP(AD19,'[2]스케줄 분석_20260109'!$B$3:$Y$20,23,FALSE)*(VLOOKUP(AD19,'[2]스케줄 분석_20260109'!$B$3:$Y$20,21,FALSE)/VLOOKUP(AD19,'[2]스케줄 분석_20260109'!$B$3:$Y$20,20,FALSE))*VLOOKUP(AD19,'[2]스케줄 분석_20260109'!$B$3:$Y$20,22,FALSE)*VLOOKUP(AD19,'[2]스케줄 분석_20260109'!$B$3:$Y$20,2,FALSE)*1.5*BI19,0),0) -> 0 | BQ19: =IF(BI19>=$D$1,"적합","미달") -> 적합 | BS19: =IF(AT19="통상",BI19*8*5,IF(OR(AT19="스케줄",AT19="스케줄_파라"),BI19*100,"확인")) -> 957224.8 | BT19: =BG19+BS19/12 -> 5619768.7 | BU19: =(BF19-BO19*12)*0.0475 -> 3043800 | BV19: =(BF19-BO19*12)*0.036+(BF19-BO19*12)*0.036*0.1314 -> 2610004 | BW19: =(BF19-BO19*12)*(0.009+0.0065) -> 993240 | BX19: =(BF19-BO19*12)*0.0066 -> 422928 | BY19: =CB19/AY19 -> 6925000 | BZ19: =SUM(BF19,BS19:BT19) -> 73056994 | CA19: =SUM(BU19:BX19) -> 7069972 | CB19: =BF19*1.25 -> 83100000 | CC19: =AZ19-CB19-BP19*1.21 -> 5160000 | CD19: =IFERROR((CC19/AZ19)*100,0) -> 5.846363 | CI19: 신장 심하지 않은 장애
A20: =ROW()-3 -> 17 | B20: Yes | C20: 2014016 | D20: 박귀진 M, 송수근 위원 | E20: 조원석 | F20: 조원석 | G20: 부장 | H20: 고급하 | I20: 고급기술자 | J20: 하도급(FTE) | K20: 서비스 관제 센터장 | M20: 02-829-2382 | N20: 010-8706-7076 | O20: chobung@cnthoth.com | P20: 701001-1 | Q20: 36008 | R20: 40634 | S20: 41640 | T20: 서울 대진고등학교 | V20: 고졸 | W20: 정보처리기사 | X20: 전기산업기사 | Y20: 전기기사 | Z20: =IF(Q20<>"",$A$1-Q20,"") -> 10153 | AA20: =$A$1-R20 -> 5527 | AD20: 보라매DC_주간 | AE20: 서울특별시 | AF20: 1. Infra 운영 | AG20: 1. Infra 운영 | AH20: SK AX | AI20: SKT(보라매) | AJ20: 조원석 | AK20: 08708 | AL20: 서울시 관악구 보라매로5길 1 SK텔레콤빌딩 6F (봉천동) | AM20: 07704 | AN20: 서울특별시 강서구 강서로45다길 30-27, 109동 1002호 (화곡동, 초록아파트) | AO20: T Biz. Cloud팀 | AP20: 보라매 DC 운영 | AQ20: Facility 운영 | AR20: / 관제 운영 | AS20: 고객사 공통 / 2026년_인프라운영_HC12_1분기(4500303380-01) | AT20: 통상 | AU20: 정직원 | AV20: 씨앤토트플러스㈜ | AW20: 6316000 | AX20: 6316000 | AY20: 12 | AZ20: =AX20*AY20 -> 75792000 | BC20: 45839 | BD20: 56604000 | BE20: 57804000 | BF20: =BG20*12 -> 57804000 | BG20: =BH20+BM20+BN20+BO20 -> 4817000 | BH20: 4148800 | BI20: =ROUND((BH20+BO20)/BJ20,2) -> 20807.66 | BJ20: =IF(AT20="통상",209,VLOOKUP(AD20,'[2]스케줄 분석_20260109'!$B$3:$F$20,5,FALSE)) -> 209 | BK20: =IF(AT20="통상",15,VLOOKUP(AD20,'[2]스케줄 분석_20260109'!$B$3:$P$20,10,FALSE)) -> 15 | BL20: =IF(AT20="통상",0,VLOOKUP(AD20,'[2]스케줄 분석_20260109'!$B$3:$P$20,11,FALSE)) -> 0 | BM20: =IF(OR(AT20="통상",AT20="스케줄_파라"),ROUNDUP(BI20*BK20*1.5,-2),IF(OR(AT20="스케줄",AT20="휴직_스케줄"),ROUNDUP(BI20*BK20*0.5,-2),"확인바람")) -> 468200 | BN20: =ROUNDUP(BI20*BL20*0.5,-2) -> 0 | BO20: 200000 | BP20: =IF(OR(AT20="스케줄",AT20="스케줄_파라"),ROUNDUP(VLOOKUP(AD20,'[2]스케줄 분석_20260109'!$B$3:$Y$20,23,FALSE)*(VLOOKUP(AD20,'[2]스케줄 분석_20260109'!$B$3:$Y$20,21,FALSE)/VLOOKUP(AD20,'[2]스케줄 분석_20260109'!$B$3:$Y$20,20,FALSE))*VLOOKUP(AD20,'[2]스케줄 분석_20260109'!$B$3:$Y$20,22,FALSE)*VLOOKUP(AD20,'[2]스케줄 분석_20260109'!$B$3:$Y$20,2,FALSE)*1.5*BI20,0),0) -> 0 | BQ20: =IF(BI20>=$D$1,"적합","미달") -> 적합 | BS20: =IF(AT20="통상",BI20*8*5,IF(OR(AT20="스케줄",AT20="스케줄_파라"),BI20*100,"확인")) -> 832306.4 | BT20: =BG20+BS20/12 -> 4886358.9 | BU20: =(BF20-BO20*12)*0.0475 -> 2631690 | BV20: =(BF20-BO20*12)*0.036+(BF20-BO20*12)*0.036*0.1314 -> 2256627.1 | BW20: =(BF20-BO20*12)*(0.009+0.0065) -> 858762 | BX20: =(BF20-BO20*12)*0.0066 -> 365666.4 | BY20: =CB20/AY20 -> 6021250 | BZ20: =SUM(BF20,BS20:BT20) -> 63522665 | CA20: =SUM(BU20:BX20) -> 6112745.5 | CB20: =BF20*1.25 -> 72255000 | CC20: =AZ20-CB20-BP20*1.21 -> 3537000 | CD20: =IFERROR((CC20/AZ20)*100,0) -> 4.6667194
A21: =ROW()-3 -> 18 | B21: Yes | C21: 2014017 | D21: 박귀진 M, 이범철 M | E21: 하상영 | F21: 하상영 | G21: 부장 | H21: 고급하 | I21: 고급기술자 | J21: 하도급(FTE) | K21: IT Facility 매니저 | M21: 02-6400-6111 | N21: 010-3745-1745 | O21: hsy403@cnthoth.com | P21: 670601-1 | Q21: 33512 | R21: 40634 | S21: 41640 | T21: 서울 잠실고등학교 | V21: 고졸 | W21: 정보처리산업기사 | Z21: =IF(Q21<>"",$A$1-Q21,"") -> 12649 | AA21: =$A$1-R21 -> 5527 | AD21: SK AX_판교 B동 | AE21: 경기도 | AF21: 1. Infra 운영 | AG21: 1. Infra 운영 | AH21: SK AX | AI21: SK그룹사(공통) | AJ21: 김홍범 | AK21: 13558 | AL21: 경기도 성남시 분당구 판교로 255번길 46 SK C&C 판교캠퍼스 A동 1층 | AM21: 05783 | AN21: 서울특별시 송파구 동남로18길 9, 2동 405호 (가락동, 극동아파트) | AO21: 제조/환경Cloud팀 | AP21: Facility 운영 | AQ21: Facility 운영 | AS21: 고객사 공통 / 2026년_인프라운영_HC22_01_1분기 (4500303129-01) | AT21: 통상 | AU21: 정직원 | AV21: 씨앤토트플러스㈜ | AW21: 6600000 | AX21: 6600000 | AY21: 12 | AZ21: =AX21*AY21 -> 79200000 | BC21: 45839 | BD21: 51444000 | BE21: 52644000 | BF21: =BG21*12 -> 52644000 | BG21: =BH21+BM21+BN21+BO21 -> 4387000 | BH21: 3760600 | BI21: =ROUND((BH21+BO21)/BJ21,2) -> 18950.24 | BJ21: =IF(AT21="통상",209,VLOOKUP(AD21,'[2]스케줄 분석_20260109'!$B$3:$F$20,5,FALSE)) -> 209 | BK21: =IF(AT21="통상",15,VLOOKUP(AD21,'[2]스케줄 분석_20260109'!$B$3:$P$20,10,FALSE)) -> 15 | BL21: =IF(AT21="통상",0,VLOOKUP(AD21,'[2]스케줄 분석_20260109'!$B$3:$P$20,11,FALSE)) -> 0 | BM21: =IF(OR(AT21="통상",AT21="스케줄_파라"),ROUNDUP(BI21*BK21*1.5,-2),IF(OR(AT21="스케줄",AT21="휴직_스케줄"),ROUNDUP(BI21*BK21*0.5,-2),"확인바람")) -> 426400 | BN21: =ROUNDUP(BI21*BL21*0.5,-2) -> 0 | BO21: 200000 | BP21: =IF(OR(AT21="스케줄",AT21="스케줄_파라"),ROUNDUP(VLOOKUP(AD21,'[2]스케줄 분석_20260109'!$B$3:$Y$20,23,FALSE)*(VLOOKUP(AD21,'[2]스케줄 분석_20260109'!$B$3:$Y$20,21,FALSE)/VLOOKUP(AD21,'[2]스케줄 분석_20260109'!$B$3:$Y$20,20,FALSE))*VLOOKUP(AD21,'[2]스케줄 분석_20260109'!$B$3:$Y$20,22,FALSE)*VLOOKUP(AD21,'[2]스케줄 분석_20260109'!$B$3:$Y$20,2,FALSE)*1.5*BI21,0),0) -> 0 | BQ21: =IF(BI21>=$D$1,"적합","미달") -> 적합 | BS21: =IF(AT21="통상",BI21*8*5,IF(OR(AT21="스케줄",AT21="스케줄_파라"),BI21*100,"확인")) -> 758009.6 | BT21: =BG21+BS21/12 -> 4450167.5 | BU21: =(BF21-BO21*12)*0.0475 -> 2386590 | BV21: =(BF21-BO21*12)*0.036+(BF21-BO21*12)*0.036*0.1314 -> 2046458.2 | BW21: =(BF21-BO21*12)*(0.009+0.0065) -> 778782 | BX21: =(BF21-BO21*12)*0.0066 -> 331610.4 | BY21: =CB21/AY21 -> 5483750 | BZ21: =SUM(BF21,BS21:BT21) -> 57852177 | CA21: =SUM(BU21:BX21) -> 5543440.6 | CB21: =BF21*1.25 -> 65805000 | CC21: =AZ21-CB21-BP21*1.21 -> 13395000 | CD21: =IFERROR((CC21/AZ21)*100,0) -> 16.912879
A22: =ROW()-3 -> 19 | B22: Yes | C22: 2014021 | D22: 김태형 M | E22: 정태옥 | F22: 정태옥 | G22: 부장 | H22: 고급상 | I22: 고급기술자 | J22: 하도급(FTE) | K22: Backup/Storage 엔지니어 | M22: 02-6400-6551 | N22: 010-4948-0954 | O22: oktojung@cnthoth.com | P22: 700110-1 | Q22: 33970 | R22: 40664 | S22: 41640 | T22: 신흥대학 | V22: 전문대졸 | Z22: =IF(Q22<>"",$A$1-Q22,"") -> 12191 | AA22: =$A$1-R22 -> 5497 | AD22: 분당지웰푸르지오_수내 | AE22: 경기도 | AF22: 1. Infra 운영 | AG22: 1. Infra 운영 | AH22: SK AX | AI22: SK그룹사(공통) | AJ22: 김홍범 | AK22: 13594 | AL22: 경기도 성남시 분당구 수내로 39 분당지웰푸르지오아파트 오피스 6층 | AM22: 02248 | AN22: 서울특별시 중랑구 동일로 483, 101동 1902호 (면목4동, 두원아파트) | AO22: T Biz. Cloud팀 | AP22: Backup/Storage | AQ22: Backup/Restore 관리 | AR22: / Storage 구축 지원, 운영 | AS22: 고객사 공통 / 2026년_인프라운영_HC12_1분기(4500303380-01) | AT22: 통상 | AU22: 정직원 | AV22: 씨앤토트플러스㈜ | AW22: 8615000 | AX22: 8615000 | AY22: 12 | AZ22: =AX22*AY22 -> 103380000 | BC22: 45839 | BD22: 72900000 | BE22: 74520000 | BF22: =BG22*12 -> 74520000 | BG22: =BH22+BM22+BN22+BO22 -> 6210000 | BH22: 5406400 | BI22: =ROUND((BH22+BO22)/BJ22,2) -> 26824.88 | BJ22: =IF(AT22="통상",209,VLOOKUP(AD22,'[2]스케줄 분석_20260109'!$B$3:$F$20,5,FALSE)) -> 209 | BK22: =IF(AT22="통상",15,VLOOKUP(AD22,'[2]스케줄 분석_20260109'!$B$3:$P$20,10,FALSE)) -> 15 | BL22: =IF(AT22="통상",0,VLOOKUP(AD22,'[2]스케줄 분석_20260109'!$B$3:$P$20,11,FALSE)) -> 0 | BM22: =IF(OR(AT22="통상",AT22="스케줄_파라"),ROUNDUP(BI22*BK22*1.5,-2),IF(OR(AT22="스케줄",AT22="휴직_스케줄"),ROUNDUP(BI22*BK22*0.5,-2),"확인바람")) -> 603600 | BN22: =ROUNDUP(BI22*BL22*0.5,-2) -> 0 | BO22: 200000 | BP22: =IF(OR(AT22="스케줄",AT22="스케줄_파라"),ROUNDUP(VLOOKUP(AD22,'[2]스케줄 분석_20260109'!$B$3:$Y$20,23,FALSE)*(VLOOKUP(AD22,'[2]스케줄 분석_20260109'!$B$3:$Y$20,21,FALSE)/VLOOKUP(AD22,'[2]스케줄 분석_20260109'!$B$3:$Y$20,20,FALSE))*VLOOKUP(AD22,'[2]스케줄 분석_20260109'!$B$3:$Y$20,22,FALSE)*VLOOKUP(AD22,'[2]스케줄 분석_20260109'!$B$3:$Y$20,2,FALSE)*1.5*BI22,0),0) -> 0 | BQ22: =IF(BI22>=$D$1,"적합","미달") -> 적합 | BS22: =IF(AT22="통상",BI22*8*5,IF(OR(AT22="스케줄",AT22="스케줄_파라"),BI22*100,"확인")) -> 1072995.2 | BT22: =BG22+BS22/12 -> 6299416.3 | BU22: =(BF22-BO22*12)*0.0475 -> 3425700 | BV22: =(BF22-BO22*12)*0.036+(BF22-BO22*12)*0.036*0.1314 -> 2937476.4 | BW22: =(BF22-BO22*12)*(0.009+0.0065) -> 1117860 | BX22: =(BF22-BO22*12)*0.0066 -> 475992 | BY22: =CB22/AY22 -> 7762500 | BZ22: =SUM(BF22,BS22:BT22) -> 81892411 | CA22: =SUM(BU22:BX22) -> 7957028.4 | CB22: =BF22*1.25 -> 93150000 | CC22: =AZ22-CB22-BP22*1.21 -> 10230000 | CD22: =IFERROR((CC22/AZ22)*100,0) -> 9.8955311
A23: =ROW()-3 -> 20 | B23: Yes | C23: 2014022 | D23: 김태형 M | E23: 임정재 | F23: 임정재 | G23: 부장 | H23: 고급하 | I23: 고급기술자 | J23: 하도급(FTE) | K23: 네트워크엔지니어 | M23: 02-6100-2712 | N23: 010-3100-8444 | O23: netcomm@cnthoth.com | P23: 720810-1 | Q23: 36373 | R23: 41000 | S23: 41640 | T23: 호원대학교 | V23: 대졸 | W23: SCJP | Z23: =IF(Q23<>"",$A$1-Q23,"") -> 9788 | AA23: =$A$1-R23 -> 5161 | AD23: SKT_을지로 | AE23: 서울특별시 | AF23: 1. Infra 운영 | AG23: 1. Infra 운영 | AH23: SK AX | AI23: SKT_T타워(을지로) | AJ23: 임정재 | AK23: 04539 | AL23: 서울시 중구 을지로 65 (을지로2가) SK텔레콤빌딩 9층 IT Infra 그룹 | AM23: 03337 | AN23: 서울특별시 은평구 통일로 942-11, 202호 (불광동) | AO23: CloudControlCenter팀 | AP23: SKT 정보보안 | AQ23: 서비스 종합 장애조치 | AS23: 고객사 공통 / 2026년_인프라운영_HC10_21_1분기(4500303124-01) | AT23: 통상 | AU23: 정직원 | AV23: 씨앤토트플러스㈜ | AW23: 8373000 | AX23: 8373000 | AY23: 12 | AZ23: =AX23*AY23 -> 100476000 | BC23: 45839 | BD23: 70008000 | BE23: 71568000 | BF23: =BG23*12 -> 71568000 | BG23: =BH23+BM23+BN23+BO23 -> 5964000 | BH23: 5184300 | BI23: =ROUND((BH23+BO23)/BJ23,2) -> 25762.2 | BJ23: =IF(AT23="통상",209,VLOOKUP(AD23,'[2]스케줄 분석_20260109'!$B$3:$F$20,5,FALSE)) -> 209 | BK23: =IF(AT23="통상",15,VLOOKUP(AD23,'[2]스케줄 분석_20260109'!$B$3:$P$20,10,FALSE)) -> 15 | BL23: =IF(AT23="통상",0,VLOOKUP(AD23,'[2]스케줄 분석_20260109'!$B$3:$P$20,11,FALSE)) -> 0 | BM23: =IF(OR(AT23="통상",AT23="스케줄_파라"),ROUNDUP(BI23*BK23*1.5,-2),IF(OR(AT23="스케줄",AT23="휴직_스케줄"),ROUNDUP(BI23*BK23*0.5,-2),"확인바람")) -> 579700 | BN23: =ROUNDUP(BI23*BL23*0.5,-2) -> 0 | BO23: 200000 | BP23: =IF(OR(AT23="스케줄",AT23="스케줄_파라"),ROUNDUP(VLOOKUP(AD23,'[2]스케줄 분석_20260109'!$B$3:$Y$20,23,FALSE)*(VLOOKUP(AD23,'[2]스케줄 분석_20260109'!$B$3:$Y$20,21,FALSE)/VLOOKUP(AD23,'[2]스케줄 분석_20260109'!$B$3:$Y$20,20,FALSE))*VLOOKUP(AD23,'[2]스케줄 분석_20260109'!$B$3:$Y$20,22,FALSE)*VLOOKUP(AD23,'[2]스케줄 분석_20260109'!$B$3:$Y$20,2,FALSE)*1.5*BI23,0),0) -> 0 | BQ23: =IF(BI23>=$D$1,"적합","미달") -> 적합 | BS23: =IF(AT23="통상",BI23*8*5,IF(OR(AT23="스케줄",AT23="스케줄_파라"),BI23*100,"확인")) -> 1030488 | BT23: =BG23+BS23/12 -> 6049874 | BU23: =(BF23-BO23*12)*0.0475 -> 3285480 | BV23: =(BF23-BO23*12)*0.036+(BF23-BO23*12)*0.036*0.1314 -> 2817240.3 | BW23: =(BF23-BO23*12)*(0.009+0.0065) -> 1072104 | BX23: =(BF23-BO23*12)*0.0066 -> 456508.8 | BY23: =CB23/AY23 -> 7455000 | BZ23: =SUM(BF23,BS23:BT23) -> 78648362 | CA23: =SUM(BU23:BX23) -> 7631333.1 | CB23: =BF23*1.25 -> 89460000 | CC23: =AZ23-CB23-BP23*1.21 -> 11016000 | CD23: =IFERROR((CC23/AZ23)*100,0) -> 10.963812
A24: =ROW()-3 -> 21 | B24: Yes | C24: 2014023 | D24: 이성전 위원 | E24: 박규성 | F24: 박규성 | G24: 부장 | H24: 고급상 | I24: 고급기술자 | J24: 하도급(M/M) | K24: 네트워크엔지니어 | M24: 02-6266-6459 | N24: 010-8155-6509 | O24: gspark12@cnthoth.com | P24: 701205-1 | Q24: 33543 | R24: 41091 | S24: 41640 | T24: 한국정보기능대 | V24: 전문대졸 | W24: 정보설비기사2급 | X24: 유선설비기사2급 | Z24: =IF(Q24<>"",$A$1-Q24,"") -> 12618 | AA24: =$A$1-R24 -> 5070 | AD24: SKB 7층_동작 | AE24: 서울특별시 | AF24: 4. SKB/SK하이닉스 Infra 운영 | AG24: 4. SKB/SK하이닉스 Infra 운영 | AH24: SK AX | AI24: SKB(동작) | AJ24: 박규성 | AK24: 07063 | AL24: 서울시 동작구 여의대방로 74 (신대방동) SK브로드밴드 7층 | AM24: 07950 | AN24: 서울특별시 양천구 목동중앙북로6길 31-1, 2층 (목동) | AO24: ICT Cloud팀 | AP24: SKB N/W 운영 | AQ24: SKB N/W 운영 총괄 | AS24: 에스케이브로드밴드(주) / SKB 26년 IT장비 및 소프트웨어 유지보수_1분기(4500302989-01) | AT24: 통상 | AU24: 정직원 | AV24: 씨앤토트플러스㈜ | AW24: 7186000 | AX24: 7186000 | AY24: 12 | AZ24: =AX24*AY24 -> 86232000 | BC24: 45839 | BD24: 63204000 | BE24: 64548000 | BF24: =BG24*12 -> 64548000 | BG24: =BH24+BM24+BN24+BO24 -> 5379000 | BH24: 4656200 | BI24: =ROUND((BH24+BO24)/BJ24,2) -> 23235.41 | BJ24: =IF(AT24="통상",209,VLOOKUP(AD24,'[2]스케줄 분석_20260109'!$B$3:$F$20,5,FALSE)) -> 209 | BK24: =IF(AT24="통상",15,VLOOKUP(AD24,'[2]스케줄 분석_20260109'!$B$3:$P$20,10,FALSE)) -> 15 | BL24: =IF(AT24="통상",0,VLOOKUP(AD24,'[2]스케줄 분석_20260109'!$B$3:$P$20,11,FALSE)) -> 0 | BM24: =IF(OR(AT24="통상",AT24="스케줄_파라"),ROUNDUP(BI24*BK24*1.5,-2),IF(OR(AT24="스케줄",AT24="휴직_스케줄"),ROUNDUP(BI24*BK24*0.5,-2),"확인바람")) -> 522800 | BN24: =ROUNDUP(BI24*BL24*0.5,-2) -> 0 | BO24: 200000 | BP24: =IF(OR(AT24="스케줄",AT24="스케줄_파라"),ROUNDUP(VLOOKUP(AD24,'[2]스케줄 분석_20260109'!$B$3:$Y$20,23,FALSE)*(VLOOKUP(AD24,'[2]스케줄 분석_20260109'!$B$3:$Y$20,21,FALSE)/VLOOKUP(AD24,'[2]스케줄 분석_20260109'!$B$3:$Y$20,20,FALSE))*VLOOKUP(AD24,'[2]스케줄 분석_20260109'!$B$3:$Y$20,22,FALSE)*VLOOKUP(AD24,'[2]스케줄 분석_20260109'!$B$3:$Y$20,2,FALSE)*1.5*BI24,0),0) -> 0 | BQ24: =IF(BI24>=$D$1,"적합","미달") -> 적합 | BS24: =IF(AT24="통상",BI24*8*5,IF(OR(AT24="스케줄",AT24="스케줄_파라"),BI24*100,"확인")) -> 929416.4 | BT24: =BG24+BS24/12 -> 5456451.4 | BU24: =(BF24-BO24*12)*0.0475 -> 2952030 | BV24: =(BF24-BO24*12)*0.036+(BF24-BO24*12)*0.036*0.1314 -> 2531312.9 | BW24: =(BF24-BO24*12)*(0.009+0.0065) -> 963294 | BX24: =(BF24-BO24*12)*0.0066 -> 410176.8 | BY24: =CB24/AY24 -> 6723750 | BZ24: =SUM(BF24,BS24:BT24) -> 70933868 | CA24: =SUM(BU24:BX24) -> 6856813.7 | CB24: =BF24*1.25 -> 80685000 | CC24: =AZ24-CB24-BP24*1.21 -> 5547000 | CD24: =IFERROR((CC24/AZ24)*100,0) -> 6.4326468
A25: =ROW()-3 -> 22 | B25: Yes | C25: 2014024 | D25: 이성전 위원 | E25: 박규성(임명:신동호) | F25: 신동호 | G25: 부장 | H25: 고급상 | I25: 고급기술자 | J25: 하도급(M/M) | K25: DBA | L25: 배동환 후임 | M25: 02-6266-6907 | N25: 010-3459-0208 | O25: sdhcoo@cnthoth.com | P25: 710208-1 | Q25: 35582 | R25: 41275 | S25: 41640 | T25: 한신대학교 | V25: 대졸 | W25: 정보처리기사 | X25: OCP10g | Z25: =IF(Q25<>"",$A$1-Q25,"") -> 10579 | AA25: =$A$1-R25 -> 4886 | AD25: SKB 7층_동작 | AE25: 서울특별시 | AF25: 4. SKB/SK하이닉스 Infra 운영 | AG25: 4. SKB/SK하이닉스 Infra 운영 | AH25: SK AX | AI25: SKB(동작) | AJ25: 박규성 | AK25: 07063 | AL25: 서울시 동작구 여의대방로 74 (신대방동) SK브로드밴드 7층 | AM25: 03304 | AN25: 서울특별시 은평구 진관4로 78-7, 602동 301호 (진관동) | AO25: ICT Cloud팀 | AP25: DB 운영 | AQ25: DB 운영 | AR25: / Oracle | AS25: 에스케이브로드밴드(주) / SKB 26년 IT장비 및 소프트웨어 유지보수_1분기(4500302989-01) | AT25: 통상 | AU25: 정직원 | AV25: 씨앤토트플러스㈜ | AW25: 7186000 | AX25: 7186000 | AY25: 12 | AZ25: =AX25*AY25 -> 86232000 | BC25: 45839 | BD25: 61800000 | BE25: 63144000 | BF25: =BG25*12 -> 63144000 | BG25: =BH25+BM25+BN25+BO25 -> 5262000 | BH25: 4550500 | BI25: =ROUND((BH25+BO25)/BJ25,2) -> 22729.67 | BJ25: =IF(AT25="통상",209,VLOOKUP(AD25,'[2]스케줄 분석_20260109'!$B$3:$F$20,5,FALSE)) -> 209 | BK25: =IF(AT25="통상",15,VLOOKUP(AD25,'[2]스케줄 분석_20260109'!$B$3:$P$20,10,FALSE)) -> 15 | BL25: =IF(AT25="통상",0,VLOOKUP(AD25,'[2]스케줄 분석_20260109'!$B$3:$P$20,11,FALSE)) -> 0 | BM25: =IF(OR(AT25="통상",AT25="스케줄_파라"),ROUNDUP(BI25*BK25*1.5,-2),IF(OR(AT25="스케줄",AT25="휴직_스케줄"),ROUNDUP(BI25*BK25*0.5,-2),"확인바람")) -> 511500 | BN25: =ROUNDUP(BI25*BL25*0.5,-2) -> 0 | BO25: 200000 | BP25: =IF(OR(AT25="스케줄",AT25="스케줄_파라"),ROUNDUP(VLOOKUP(AD25,'[2]스케줄 분석_20260109'!$B$3:$Y$20,23,FALSE)*(VLOOKUP(AD25,'[2]스케줄 분석_20260109'!$B$3:$Y$20,21,FALSE)/VLOOKUP(AD25,'[2]스케줄 분석_20260109'!$B$3:$Y$20,20,FALSE))*VLOOKUP(AD25,'[2]스케줄 분석_20260109'!$B$3:$Y$20,22,FALSE)*VLOOKUP(AD25,'[2]스케줄 분석_20260109'!$B$3:$Y$20,2,FALSE)*1.5*BI25,0),0) -> 0 | BQ25: =IF(BI25>=$D$1,"적합","미달") -> 적합 | BS25: =IF(AT25="통상",BI25*8*5,IF(OR(AT25="스케줄",AT25="스케줄_파라"),BI25*100,"확인")) -> 909186.8 | BT25: =BG25+BS25/12 -> 5337765.6 | BU25: =(BF25-BO25*12)*0.0475 -> 2885340 | BV25: =(BF25-BO25*12)*0.036+(BF25-BO25*12)*0.036*0.1314 -> 2474127.4 | BW25: =(BF25-BO25*12)*(0.009+0.0065) -> 941532 | BX25: =(BF25-BO25*12)*0.0066 -> 400910.4 | BY25: =CB25/AY25 -> 6577500 | BZ25: =SUM(BF25,BS25:BT25) -> 69390952 | CA25: =SUM(BU25:BX25) -> 6701909.8 | CB25: =BF25*1.25 -> 78930000 | CC25: =AZ25-CB25-BP25*1.21 -> 7302000 | CD25: =IFERROR((CC25/AZ25)*100,0) -> 8.4678542
A26: =ROW()-3 -> 23 | B26: Yes | C26: 2014029 | D26: 김태형 M, 이범철 M | E26: 정태옥(임명:배상용) | F26: 배상용 | G26: 부장 | H26: 중급상 | I26: 중급기술자 | J26: 하도급(FTE) | K26: M/W 엔지니어 | M26: 02-6900-7095 | N26: 010-8668-2882 | O26: hollowmind@cnthoth.com | P26: 761203-1 | Q26: 38112 | R26: 40360 | S26: 41640 | T26: 전북대학교 | V26: 대졸 | Z26: =IF(Q26<>"",$A$1-Q26,"") -> 8049 | AA26: =$A$1-R26 -> 5801 | AD26: 분당지웰푸르지오_수내 | AE26: 경기도 | AF26: 1. Infra 운영 | AG26: 1. Infra 운영 | AH26: SK AX | AI26: SK그룹사(공통) | AJ26: 김홍범 | AK26: 13594 | AL26: 경기도 성남시 분당구 수내로 39 분당지웰푸르지오아파트 오피스 6층 | AM26: 16817 | AN26: 경기도 용인시 수지구 신봉2로 26, 108동 504호 (신봉동, 신봉마을엘지자이1차아파트) | AO26: T Biz. Cloud팀 | AP26: Middleware 운영 | AQ26: WAS 운영 | AS26: 고객사 공통 / 2026년_인프라운영_HC12_1분기(4500303380-01) | AT26: 통상 | AU26: 정직원 | AV26: 씨앤토트플러스㈜ | AW26: 6800000 | AX26: 6800000 | AY26: 12 | AZ26: =AX26*AY26 -> 81600000 | BC26: 45839 | BD26: 51408000 | BE26: 52608000 | BF26: =BG26*12 -> 52608000 | BG26: =BH26+BM26+BN26+BO26 -> 4384000 | BH26: 3757900 | BI26: =ROUND((BH26+BO26)/BJ26,2) -> 18937.32 | BJ26: =IF(AT26="통상",209,VLOOKUP(AD26,'[2]스케줄 분석_20260109'!$B$3:$F$20,5,FALSE)) -> 209 | BK26: =IF(AT26="통상",15,VLOOKUP(AD26,'[2]스케줄 분석_20260109'!$B$3:$P$20,10,FALSE)) -> 15 | BL26: =IF(AT26="통상",0,VLOOKUP(AD26,'[2]스케줄 분석_20260109'!$B$3:$P$20,11,FALSE)) -> 0 | BM26: =IF(OR(AT26="통상",AT26="스케줄_파라"),ROUNDUP(BI26*BK26*1.5,-2),IF(OR(AT26="스케줄",AT26="휴직_스케줄"),ROUNDUP(BI26*BK26*0.5,-2),"확인바람")) -> 426100 | BN26: =ROUNDUP(BI26*BL26*0.5,-2) -> 0 | BO26: 200000 | BP26: =IF(OR(AT26="스케줄",AT26="스케줄_파라"),ROUNDUP(VLOOKUP(AD26,'[2]스케줄 분석_20260109'!$B$3:$Y$20,23,FALSE)*(VLOOKUP(AD26,'[2]스케줄 분석_20260109'!$B$3:$Y$20,21,FALSE)/VLOOKUP(AD26,'[2]스케줄 분석_20260109'!$B$3:$Y$20,20,FALSE))*VLOOKUP(AD26,'[2]스케줄 분석_20260109'!$B$3:$Y$20,22,FALSE)*VLOOKUP(AD26,'[2]스케줄 분석_20260109'!$B$3:$Y$20,2,FALSE)*1.5*BI26,0),0) -> 0 | BQ26: =IF(BI26>=$D$1,"적합","미달") -> 적합 | BS26: =IF(AT26="통상",BI26*8*5,IF(OR(AT26="스케줄",AT26="스케줄_파라"),BI26*100,"확인")) -> 757492.8 | BT26: =BG26+BS26/12 -> 4447124.4 | BU26: =(BF26-BO26*12)*0.0475 -> 2384880 | BV26: =(BF26-BO26*12)*0.036+(BF26-BO26*12)*0.036*0.1314 -> 2044991.9 | BW26: =(BF26-BO26*12)*(0.009+0.0065) -> 778224 | BX26: =(BF26-BO26*12)*0.0066 -> 331372.8 | BY26: =CB26/AY26 -> 5480000 | BZ26: =SUM(BF26,BS26:BT26) -> 57812617 | CA26: =SUM(BU26:BX26) -> 5539468.7 | CB26: =BF26*1.25 -> 65760000 | CC26: =AZ26-CB26-BP26*1.21 -> 15840000 | CD26: =IFERROR((CC26/AZ26)*100,0) -> 19.411765
A27: =ROW()-3 -> 24 | B27: Yes | C27: 2014039 | D27: 민승기 M. 김홍섭 M | E27: 김홍범 | F27: 김홍범 | G27: 부장 | H27: 중급하 | I27: 중급기술자 | J27: 하도급(FTE) | K27: 시스템엔지니어 | M27: 02-6400-6043 | N27: 010-8685-7893 | O27: victor20@cnthoth.com | P27: 710103-1 | Q27: 35034 | R27: 40634 | S27: 41640 | T27: 충남전산전문대 | V27: 전문대졸 | W27: CSA | X27: 해상무선통신사 | Y27: 정보기기운용기능사 | Z27: =IF(Q27<>"",$A$1-Q27,"") -> 11127 | AA27: =$A$1-R27 -> 5527 | AD27: SK㈜ U타워_정자 | AE27: 경기도 | AF27: 1. Infra 운영 | AG27: 1. Infra 운영 | AH27: SK AX | AI27: SK그룹사(공통) | AJ27: 김홍범 | AK27: 13558 | AL27: 경기도 성남시 분당구 성남대로 343번길 9 SK U타워 23층 | AM27: 13584 | AN27: 경기도 성남시 분당구 서현로494번길 8-10 (분당동) | AO27: Cloud VDI팀 | AP27: 긴급 장애대응 | AQ27: 인프라 종합 장애조치 | AS27: 고객사 공통 / 2026년_VDI_01_1분기 (4500303359-01) | AT27: 통상 | AU27: 정직원 | AV27: 씨앤토트플러스㈜ | AW27: 5320000 | AX27: 5320000 | AY27: 12 | AZ27: =AX27*AY27 -> 63840000 | BC27: 45839 | BD27: 43308000 | BE27: 44316000 | BF27: =BG27*12 -> 44316000 | BG27: =BH27+BM27+BN27+BO27 -> 3693000 | BH27: 3134000 | BI27: =ROUND((BH27+BO27)/BJ27,2) -> 15952.15 | BJ27: =IF(AT27="통상",209,VLOOKUP(AD27,'[2]스케줄 분석_20260109'!$B$3:$F$20,5,FALSE)) -> 209 | BK27: =IF(AT27="통상",15,VLOOKUP(AD27,'[2]스케줄 분석_20260109'!$B$3:$P$20,10,FALSE)) -> 15 | BL27: =IF(AT27="통상",0,VLOOKUP(AD27,'[2]스케줄 분석_20260109'!$B$3:$P$20,11,FALSE)) -> 0 | BM27: =IF(OR(AT27="통상",AT27="스케줄_파라"),ROUNDUP(BI27*BK27*1.5,-2),IF(OR(AT27="스케줄",AT27="휴직_스케줄"),ROUNDUP(BI27*BK27*0.5,-2),"확인바람")) -> 359000 | BN27: =ROUNDUP(BI27*BL27*0.5,-2) -> 0 | BO27: 200000 | BP27: =IF(OR(AT27="스케줄",AT27="스케줄_파라"),ROUNDUP(VLOOKUP(AD27,'[2]스케줄 분석_20260109'!$B$3:$Y$20,23,FALSE)*(VLOOKUP(AD27,'[2]스케줄 분석_20260109'!$B$3:$Y$20,21,FALSE)/VLOOKUP(AD27,'[2]스케줄 분석_20260109'!$B$3:$Y$20,20,FALSE))*VLOOKUP(AD27,'[2]스케줄 분석_20260109'!$B$3:$Y$20,22,FALSE)*VLOOKUP(AD27,'[2]스케줄 분석_20260109'!$B$3:$Y$20,2,FALSE)*1.5*BI27,0),0) -> 0 | BQ27: =IF(BI27>=$D$1,"적합","미달") -> 적합 | BS27: =IF(AT27="통상",BI27*8*5,IF(OR(AT27="스케줄",AT27="스케줄_파라"),BI27*100,"확인")) -> 638086 | BT27: =BG27+BS27/12 -> 3746173.8 | BU27: =(BF27-BO27*12)*0.0475 -> 1991010 | BV27: =(BF27-BO27*12)*0.036+(BF27-BO27*12)*0.036*0.1314 -> 1707255.4 | BW27: =(BF27-BO27*12)*(0.009+0.0065) -> 649698 | BX27: =(BF27-BO27*12)*0.0066 -> 276645.6 | BY27: =CB27/AY27 -> 4616250 | BZ27: =SUM(BF27,BS27:BT27) -> 48700260 | CA27: =SUM(BU27:BX27) -> 4624609 | CB27: =BF27*1.25 -> 55395000 | CC27: =AZ27-CB27-BP27*1.21 -> 8445000 | CD27: =IFERROR((CC27/AZ27)*100,0) -> 13.228383
A28: =ROW()-3 -> 25 | B28: Yes | C28: 2014040 | D28: 김태형 M | E28: 김홍범(임명:서상우) | F28: 서상우 | G28: 부장 | H28: 고급상 | I28: 고급기술자 | J28: 하도급(FTE) | K28: 시스템엔지니어 | M28: 02-6400-6042 | N28: 010-3755-8429 | O28: unish99@cnthoth.com | P28: 720718-1 | Q28: 34851 | R28: 40634 | S28: 41640 | T28: 현대전산원 | V28: 전문대졸 | W28: 정보처리기사 | Z28: =IF(Q28<>"",$A$1-Q28,"") -> 11310 | AA28: =$A$1-R28 -> 5527 | AD28: 분당지웰푸르지오_수내 | AE28: 경기도 | AF28: 1. Infra 운영 | AG28: 1. Infra 운영 | AH28: SK AX | AI28: SK그룹사(공통) | AJ28: 김홍범 | AK28: 13594 | AL28: 경기도 성남시 분당구 수내로 39 분당지웰푸르지오아파트 오피스 6층 | AM28: 18407 | AN28: 경기도 화성시 병점2로 141 603동 707호(병점동 안화동마을주공아파트) | AO28: CloudControlCenter팀 | AP28: 긴급 장애대응 | AQ28: 인프라 종합 장애조치 | AS28: 고객사 공통 / 2026년_인프라운영_HC10_21_1분기(4500303124-01) | AT28: 통상 | AU28: 정직원 | AV28: 씨앤토트플러스㈜ | AW28: 7040000 | AX28: 7040000 | AY28: 12 | AZ28: =AX28*AY28 -> 84480000 | BC28: 45839 | BD28: 55404000 | BE28: 56736000 | BF28: =BG28*12 -> 56736000 | BG28: =BH28+BM28+BN28+BO28 -> 4728000 | BH28: 4068400 | BI28: =ROUND((BH28+BO28)/BJ28,2) -> 20422.97 | BJ28: =IF(AT28="통상",209,VLOOKUP(AD28,'[2]스케줄 분석_20260109'!$B$3:$F$20,5,FALSE)) -> 209 | BK28: =IF(AT28="통상",15,VLOOKUP(AD28,'[2]스케줄 분석_20260109'!$B$3:$P$20,10,FALSE)) -> 15 | BL28: =IF(AT28="통상",0,VLOOKUP(AD28,'[2]스케줄 분석_20260109'!$B$3:$P$20,11,FALSE)) -> 0 | BM28: =IF(OR(AT28="통상",AT28="스케줄_파라"),ROUNDUP(BI28*BK28*1.5,-2),IF(OR(AT28="스케줄",AT28="휴직_스케줄"),ROUNDUP(BI28*BK28*0.5,-2),"확인바람")) -> 459600 | BN28: =ROUNDUP(BI28*BL28*0.5,-2) -> 0 | BO28: 200000 | BP28: =IF(OR(AT28="스케줄",AT28="스케줄_파라"),ROUNDUP(VLOOKUP(AD28,'[2]스케줄 분석_20260109'!$B$3:$Y$20,23,FALSE)*(VLOOKUP(AD28,'[2]스케줄 분석_20260109'!$B$3:$Y$20,21,FALSE)/VLOOKUP(AD28,'[2]스케줄 분석_20260109'!$B$3:$Y$20,20,FALSE))*VLOOKUP(AD28,'[2]스케줄 분석_20260109'!$B$3:$Y$20,22,FALSE)*VLOOKUP(AD28,'[2]스케줄 분석_20260109'!$B$3:$Y$20,2,FALSE)*1.5*BI28,0),0) -> 0 | BQ28: =IF(BI28>=$D$1,"적합","미달") -> 적합 | BS28: =IF(AT28="통상",BI28*8*5,IF(OR(AT28="스케줄",AT28="스케줄_파라"),BI28*100,"확인")) -> 816918.8 | BT28: =BG28+BS28/12 -> 4796076.6 | BU28: =(BF28-BO28*12)*0.0475 -> 2580960 | BV28: =(BF28-BO28*12)*0.036+(BF28-BO28*12)*0.036*0.1314 -> 2213127 | BW28: =(BF28-BO28*12)*(0.009+0.0065) -> 842208 | BX28: =(BF28-BO28*12)*0.0066 -> 358617.6 | BY28: =CB28/AY28 -> 5910000 | BZ28: =SUM(BF28,BS28:BT28) -> 62348995 | CA28: =SUM(BU28:BX28) -> 5994912.6 | CB28: =BF28*1.25 -> 70920000 | CC28: =AZ28-CB28-BP28*1.21 -> 13560000 | CD28: =IFERROR((CC28/AZ28)*100,0) -> 16.051136
A29: =ROW()-3 -> 26 | B29: Yes | C29: 2014041 | D29: 박귀진 M, 이범철 M | E29: 김명국 | F29: 김명국 | G29: 부장 | H29: 중급상 | I29: 중급기술자 | J29: 하도급(FTE) | K29: 서버엔지니어 | N29: 010-8923-1140 | O29: hongtae70@cnthoth.com | P29: 700911-1 | Q29: 36617 | R29: 40634 | S29: 41640 | T29: 동서울대학 | V29: 전문대졸 | Z29: =IF(Q29<>"",$A$1-Q29,"") -> 9544 | AA29: =$A$1-R29 -> 5527 | AD29: SK㈜ U타워_정자 | AE29: 경기도 | AF29: 1. Infra 운영 | AG29: 1. Infra 운영 | AH29: SK AX | AI29: SK네트웍스 | AJ29: 개인 | AK29: 13558 | AL29: 경기도 성남시 분당구 성남대로 343번길 9 SK U타워 19층 | AM29: 04984 | AN29: 서울특별시 광진구 아차산로 503-23, 102동 501호 (광장동, 청구아파트) | AO29: 제조/환경Cloud팀 | AP29: SK네트웍스 서버 운영 | AQ29: Unix 서버 운영 | AS29: 고객사 공통 / 2026년_인프라운영_HC22_01_1분기 (4500303129-01) | AT29: 통상 | AU29: 정직원 | AV29: 씨앤토트플러스㈜ | AW29: 5929000 | AX29: 5929000 | AY29: 12 | AZ29: =AX29*AY29 -> 71148000 | BC29: 45839 | BD29: 48708000 | BE29: 49824000 | BF29: =BG29*12 -> 49824000 | BG29: =BH29+BM29+BN29+BO29 -> 4152000 | BH29: 3548400 | BI29: =ROUND((BH29+BO29)/BJ29,2) -> 17934.93 | BJ29: =IF(AT29="통상",209,VLOOKUP(AD29,'[2]스케줄 분석_20260109'!$B$3:$F$20,5,FALSE)) -> 209 | BK29: =IF(AT29="통상",15,VLOOKUP(AD29,'[2]스케줄 분석_20260109'!$B$3:$P$20,10,FALSE)) -> 15 | BL29: =IF(AT29="통상",0,VLOOKUP(AD29,'[2]스케줄 분석_20260109'!$B$3:$P$20,11,FALSE)) -> 0 | BM29: =IF(OR(AT29="통상",AT29="스케줄_파라"),ROUNDUP(BI29*BK29*1.5,-2),IF(OR(AT29="스케줄",AT29="휴직_스케줄"),ROUNDUP(BI29*BK29*0.5,-2),"확인바람")) -> 403600 | BN29: =ROUNDUP(BI29*BL29*0.5,-2) -> 0 | BO29: 200000 | BP29: =IF(OR(AT29="스케줄",AT29="스케줄_파라"),ROUNDUP(VLOOKUP(AD29,'[2]스케줄 분석_20260109'!$B$3:$Y$20,23,FALSE)*(VLOOKUP(AD29,'[2]스케줄 분석_20260109'!$B$3:$Y$20,21,FALSE)/VLOOKUP(AD29,'[2]스케줄 분석_20260109'!$B$3:$Y$20,20,FALSE))*VLOOKUP(AD29,'[2]스케줄 분석_20260109'!$B$3:$Y$20,22,FALSE)*VLOOKUP(AD29,'[2]스케줄 분석_20260109'!$B$3:$Y$20,2,FALSE)*1.5*BI29,0),0) -> 0 | BQ29: =IF(BI29>=$D$1,"적합","미달") -> 적합 | BS29: =IF(AT29="통상",BI29*8*5,IF(OR(AT29="스케줄",AT29="스케줄_파라"),BI29*100,"확인")) -> 717397.2 | BT29: =BG29+BS29/12 -> 4211783.1 | BU29: =(BF29-BO29*12)*0.0475 -> 2252640 | BV29: =(BF29-BO29*12)*0.036+(BF29-BO29*12)*0.036*0.1314 -> 1931598.5 | BW29: =(BF29-BO29*12)*(0.009+0.0065) -> 735072 | BX29: =(BF29-BO29*12)*0.0066 -> 312998.4 | BY29: =CB29/AY29 -> 5190000 | BZ29: =SUM(BF29,BS29:BT29) -> 54753180 | CA29: =SUM(BU29:BX29) -> 5232308.9 | CB29: =BF29*1.25 -> 62280000 | CC29: =AZ29-CB29-BP29*1.21 -> 8868000 | CD29: =IFERROR((CC29/AZ29)*100,0) -> 12.464159
